Watching for file changes with StatReloader
Watching for file changes with StatReloader
Watching for file changes with StatReloader
Watching for file changes with StatReloader
Watching for file changes with StatReloader
Watching for file changes with StatReloader
Watching for file changes with StatReloader
Watching for file changes with StatReloader
Watching for file changes with StatReloader
Watching for file changes with StatReloader
Watching for file changes with StatReloader
Watching for file changes with StatReloader
Watching for file changes with StatReloader
Watching for file changes with StatReloader
Watching for file changes with StatReloader
Watching for file changes with StatReloader
Watching for file changes with StatReloader
Watching for file changes with StatReloader
Watching for file changes with StatReloader
Watching for file changes with StatReloader
Watching for file changes with StatReloader
Watching for file changes with StatReloader
Watching for file changes with StatReloader
Watching for file changes with StatReloader
Watching for file changes with StatReloader
Watching for file changes with StatReloader
Watching for file changes with StatReloader
Watching for file changes with StatReloader
Watching for file changes with StatReloader
Watching for file changes with StatReloader
Watching for file changes with StatReloader
run server
Watching for file changes with StatReloader
run server
Watching for file changes with StatReloader
Watching for file changes with StatReloader
Watching for file changes with StatReloader
run server
Watching for file changes with StatReloader
Watching for file changes with StatReloader
Watching for file changes with StatReloader
run server
Watching for file changes with StatReloader
Internal Server Error: /pizzas/
Traceback (most recent call last):
  File "C:\Users\holmi\PycharmProjects\djangoProject\.venv\Lib\site-packages\django\core\handlers\exception.py", line 55, in inner
    response = get_response(request)
               ^^^^^^^^^^^^^^^^^^^^^
  File "C:\Users\holmi\PycharmProjects\djangoProject\.venv\Lib\site-packages\django\core\handlers\base.py", line 197, in _get_response
    response = wrapped_callback(request, *callback_args, **callback_kwargs)
               ^^^^^^^^^^^^^^^^^^^^^^^^^^^^^^^^^^^^^^^^^^^^^^^^^^^^^^^^^^^^
  File "C:\Users\holmi\PycharmProjects\djangoProject\.venv\Lib\site-packages\django\views\decorators\csrf.py", line 65, in _view_wrapper
    return view_func(request, *args, **kwargs)
           ^^^^^^^^^^^^^^^^^^^^^^^^^^^^^^^^^^^
  File "C:\Users\holmi\PycharmProjects\djangoProject\.venv\Lib\site-packages\django\views\generic\base.py", line 104, in view
    return self.dispatch(request, *args, **kwargs)
           ^^^^^^^^^^^^^^^^^^^^^^^^^^^^^^^^^^^^^^^
  File "C:\Users\holmi\PycharmProjects\djangoProject\.venv\Lib\site-packages\rest_framework\views.py", line 509, in dispatch
    response = self.handle_exception(exc)
               ^^^^^^^^^^^^^^^^^^^^^^^^^^
  File "C:\Users\holmi\PycharmProjects\djangoProject\.venv\Lib\site-packages\rest_framework\views.py", line 469, in handle_exception
    self.raise_uncaught_exception(exc)
  File "C:\Users\holmi\PycharmProjects\djangoProject\.venv\Lib\site-packages\rest_framework\views.py", line 480, in raise_uncaught_exception
    raise exc
  File "C:\Users\holmi\PycharmProjects\djangoProject\.venv\Lib\site-packages\rest_framework\views.py", line 506, in dispatch
    response = handler(request, *args, **kwargs)
               ^^^^^^^^^^^^^^^^^^^^^^^^^^^^^^^^^
  File "C:\Users\holmi\PycharmProjects\djangoProject\.venv\Lib\site-packages\rest_framework\generics.py", line 282, in get
    return self.retrieve(request, *args, **kwargs)
           ^^^^^^^^^^^^^^^^^^^^^^^^^^^^^^^^^^^^^^^
  File "C:\Users\holmi\PycharmProjects\djangoProject\.venv\Lib\site-packages\rest_framework\mixins.py", line 54, in retrieve
    instance = self.get_object()
               ^^^^^^^^^^^^^^^^^
  File "C:\Users\holmi\PycharmProjects\djangoProject\.venv\Lib\site-packages\rest_framework\generics.py", line 88, in get_object
    assert lookup_url_kwarg in self.kwargs, (
AssertionError: Expected view PizzaViewSet to be called with a URL keyword argument named "pk". Fix your URL conf, or set the `.lookup_field` attribute on the view correctly.
Internal Server Error: /pizzas/
Traceback (most recent call last):
  File "C:\Users\holmi\PycharmProjects\djangoProject\.venv\Lib\site-packages\django\core\handlers\exception.py", line 55, in inner
    response = get_response(request)
               ^^^^^^^^^^^^^^^^^^^^^
  File "C:\Users\holmi\PycharmProjects\djangoProject\.venv\Lib\site-packages\django\core\handlers\base.py", line 197, in _get_response
    response = wrapped_callback(request, *callback_args, **callback_kwargs)
               ^^^^^^^^^^^^^^^^^^^^^^^^^^^^^^^^^^^^^^^^^^^^^^^^^^^^^^^^^^^^
  File "C:\Users\holmi\PycharmProjects\djangoProject\.venv\Lib\site-packages\django\views\decorators\csrf.py", line 65, in _view_wrapper
    return view_func(request, *args, **kwargs)
           ^^^^^^^^^^^^^^^^^^^^^^^^^^^^^^^^^^^
  File "C:\Users\holmi\PycharmProjects\djangoProject\.venv\Lib\site-packages\django\views\generic\base.py", line 104, in view
    return self.dispatch(request, *args, **kwargs)
           ^^^^^^^^^^^^^^^^^^^^^^^^^^^^^^^^^^^^^^^
  File "C:\Users\holmi\PycharmProjects\djangoProject\.venv\Lib\site-packages\rest_framework\views.py", line 509, in dispatch
    response = self.handle_exception(exc)
               ^^^^^^^^^^^^^^^^^^^^^^^^^^
  File "C:\Users\holmi\PycharmProjects\djangoProject\.venv\Lib\site-packages\rest_framework\views.py", line 469, in handle_exception
    self.raise_uncaught_exception(exc)
  File "C:\Users\holmi\PycharmProjects\djangoProject\.venv\Lib\site-packages\rest_framework\views.py", line 480, in raise_uncaught_exception
    raise exc
  File "C:\Users\holmi\PycharmProjects\djangoProject\.venv\Lib\site-packages\rest_framework\views.py", line 506, in dispatch
    response = handler(request, *args, **kwargs)
               ^^^^^^^^^^^^^^^^^^^^^^^^^^^^^^^^^
  File "C:\Users\holmi\PycharmProjects\djangoProject\.venv\Lib\site-packages\rest_framework\generics.py", line 282, in get
    return self.retrieve(request, *args, **kwargs)
           ^^^^^^^^^^^^^^^^^^^^^^^^^^^^^^^^^^^^^^^
  File "C:\Users\holmi\PycharmProjects\djangoProject\.venv\Lib\site-packages\rest_framework\mixins.py", line 54, in retrieve
    instance = self.get_object()
               ^^^^^^^^^^^^^^^^^
  File "C:\Users\holmi\PycharmProjects\djangoProject\.venv\Lib\site-packages\rest_framework\generics.py", line 88, in get_object
    assert lookup_url_kwarg in self.kwargs, (
AssertionError: Expected view PizzaViewSet to be called with a URL keyword argument named "pk". Fix your URL conf, or set the `.lookup_field` attribute on the view correctly.
Watching for file changes with StatReloader
Method Not Allowed: /pizzas/
Bad Request: /pizzas/
Watching for file changes with StatReloader
Method Not Allowed: /pizzas/
C:\Users\holmi\PycharmProjects\djangoProject\Mamma_Mia\views.py changed, reloading.
Watching for file changes with StatReloader
Watching for file changes with StatReloader
Not Found: /pizzas/4/
Not Found: /pizzas/4
Not Found: /pizzas/4
Not Found: /pizzas/4/
C:\Users\holmi\PycharmProjects\djangoProject\Mamma_Mia\urls.py changed, reloading.
Watching for file changes with StatReloader
Watching for file changes with StatReloader
Bad Request: /pizza/create/
Watching for file changes with StatReloader
Watching for file changes with StatReloader
Bad Request: /pizza/create/
Bad Request: /pizza/create/
Bad Request: /pizza/create/
Bad Request: /pizza/create/
Forbidden (CSRF cookie not set.): /
run server
Watching for file changes with StatReloader
Watching for file changes with StatReloader
C:\Users\holmi\PycharmProjects\djangoProject\Mamma_Mia\views.py changed, reloading.
Watching for file changes with StatReloader
Watching for file changes with StatReloader
Watching for file changes with StatReloader
Watching for file changes with StatReloader
Watching for file changes with StatReloader
Watching for file changes with StatReloader
Watching for file changes with StatReloader
Watching for file changes with StatReloader
C:\Users\holmi\PycharmProjects\djangoProject\Mamma_Mia\views.py changed, reloading.
Watching for file changes with StatReloader
Watching for file changes with StatReloader
Watching for file changes with StatReloader
C:\Users\holmi\PycharmProjects\djangoProject\Mamma_Mia\views.py changed, reloading.
Watching for file changes with StatReloader
Watching for file changes with StatReloader
Watching for file changes with StatReloader
C:\Users\holmi\PycharmProjects\djangoProject\Mamma_Mia\views.py changed, reloading.
Watching for file changes with StatReloader
Watching for file changes with StatReloader
Internal Server Error: /ingredients/
Traceback (most recent call last):
  File "C:\Users\holmi\PycharmProjects\djangoProject\.venv\Lib\site-packages\django\db\backends\utils.py", line 105, in _execute
    return self.cursor.execute(sql, params)
           ^^^^^^^^^^^^^^^^^^^^^^^^^^^^^^^^
psycopg2.errors.UndefinedTable: ОШИБКА:  отношение "Mamma_Mia_ingredient" не существует
LINE 1: ...redient"."id", "Mamma_Mia_ingredient"."name" FROM "Mamma_Mia...
                                                             ^


The above exception was the direct cause of the following exception:

Traceback (most recent call last):
  File "C:\Users\holmi\PycharmProjects\djangoProject\.venv\Lib\site-packages\django\core\handlers\exception.py", line 55, in inner
    response = get_response(request)
               ^^^^^^^^^^^^^^^^^^^^^
  File "C:\Users\holmi\PycharmProjects\djangoProject\.venv\Lib\site-packages\django\core\handlers\base.py", line 197, in _get_response
    response = wrapped_callback(request, *callback_args, **callback_kwargs)
               ^^^^^^^^^^^^^^^^^^^^^^^^^^^^^^^^^^^^^^^^^^^^^^^^^^^^^^^^^^^^
  File "C:\Users\holmi\PycharmProjects\djangoProject\.venv\Lib\site-packages\django\views\decorators\csrf.py", line 65, in _view_wrapper
    return view_func(request, *args, **kwargs)
           ^^^^^^^^^^^^^^^^^^^^^^^^^^^^^^^^^^^
  File "C:\Users\holmi\PycharmProjects\djangoProject\.venv\Lib\site-packages\django\views\generic\base.py", line 104, in view
    return self.dispatch(request, *args, **kwargs)
           ^^^^^^^^^^^^^^^^^^^^^^^^^^^^^^^^^^^^^^^
  File "C:\Users\holmi\PycharmProjects\djangoProject\.venv\Lib\site-packages\rest_framework\views.py", line 509, in dispatch
    response = self.handle_exception(exc)
               ^^^^^^^^^^^^^^^^^^^^^^^^^^
  File "C:\Users\holmi\PycharmProjects\djangoProject\.venv\Lib\site-packages\rest_framework\views.py", line 469, in handle_exception
    self.raise_uncaught_exception(exc)
  File "C:\Users\holmi\PycharmProjects\djangoProject\.venv\Lib\site-packages\rest_framework\views.py", line 480, in raise_uncaught_exception
    raise exc
  File "C:\Users\holmi\PycharmProjects\djangoProject\.venv\Lib\site-packages\rest_framework\views.py", line 506, in dispatch
    response = handler(request, *args, **kwargs)
               ^^^^^^^^^^^^^^^^^^^^^^^^^^^^^^^^^
  File "C:\Users\holmi\PycharmProjects\djangoProject\.venv\Lib\site-packages\rest_framework\generics.py", line 239, in get
    return self.list(request, *args, **kwargs)
           ^^^^^^^^^^^^^^^^^^^^^^^^^^^^^^^^^^^
  File "C:\Users\holmi\PycharmProjects\djangoProject\.venv\Lib\site-packages\rest_framework\mixins.py", line 46, in list
    return Response(serializer.data)
                    ^^^^^^^^^^^^^^^
  File "C:\Users\holmi\PycharmProjects\djangoProject\.venv\Lib\site-packages\rest_framework\serializers.py", line 768, in data
    ret = super().data
          ^^^^^^^^^^^^
  File "C:\Users\holmi\PycharmProjects\djangoProject\.venv\Lib\site-packages\rest_framework\serializers.py", line 253, in data
    self._data = self.to_representation(self.instance)
                 ^^^^^^^^^^^^^^^^^^^^^^^^^^^^^^^^^^^^^
  File "C:\Users\holmi\PycharmProjects\djangoProject\.venv\Lib\site-packages\rest_framework\serializers.py", line 686, in to_representation
    return [
           ^
  File "C:\Users\holmi\PycharmProjects\djangoProject\.venv\Lib\site-packages\django\db\models\query.py", line 400, in __iter__
    self._fetch_all()
  File "C:\Users\holmi\PycharmProjects\djangoProject\.venv\Lib\site-packages\django\db\models\query.py", line 1928, in _fetch_all
    self._result_cache = list(self._iterable_class(self))
                         ^^^^^^^^^^^^^^^^^^^^^^^^^^^^^^^^
  File "C:\Users\holmi\PycharmProjects\djangoProject\.venv\Lib\site-packages\django\db\models\query.py", line 91, in __iter__
    results = compiler.execute_sql(
              ^^^^^^^^^^^^^^^^^^^^^
  File "C:\Users\holmi\PycharmProjects\djangoProject\.venv\Lib\site-packages\django\db\models\sql\compiler.py", line 1562, in execute_sql
    cursor.execute(sql, params)
  File "C:\Users\holmi\PycharmProjects\djangoProject\.venv\Lib\site-packages\django\db\backends\utils.py", line 122, in execute
    return super().execute(sql, params)
           ^^^^^^^^^^^^^^^^^^^^^^^^^^^^
  File "C:\Users\holmi\PycharmProjects\djangoProject\.venv\Lib\site-packages\django\db\backends\utils.py", line 79, in execute
    return self._execute_with_wrappers(
           ^^^^^^^^^^^^^^^^^^^^^^^^^^^^
  File "C:\Users\holmi\PycharmProjects\djangoProject\.venv\Lib\site-packages\django\db\backends\utils.py", line 92, in _execute_with_wrappers
    return executor(sql, params, many, context)
           ^^^^^^^^^^^^^^^^^^^^^^^^^^^^^^^^^^^^
  File "C:\Users\holmi\PycharmProjects\djangoProject\.venv\Lib\site-packages\django\db\backends\utils.py", line 100, in _execute
    with self.db.wrap_database_errors:
  File "C:\Users\holmi\PycharmProjects\djangoProject\.venv\Lib\site-packages\django\db\utils.py", line 91, in __exit__
    raise dj_exc_value.with_traceback(traceback) from exc_value
  File "C:\Users\holmi\PycharmProjects\djangoProject\.venv\Lib\site-packages\django\db\backends\utils.py", line 105, in _execute
    return self.cursor.execute(sql, params)
           ^^^^^^^^^^^^^^^^^^^^^^^^^^^^^^^^
django.db.utils.ProgrammingError: ОШИБКА:  отношение "Mamma_Mia_ingredient" не существует
LINE 1: ...redient"."id", "Mamma_Mia_ingredient"."name" FROM "Mamma_Mia...
                                                             ^

Watching for file changes with StatReloader
Watching for file changes with StatReloader
Watching for file changes with StatReloader
Internal Server Error: /ingredients/
Traceback (most recent call last):
  File "C:\Users\holmi\PycharmProjects\djangoProject\.venv\Lib\site-packages\django\db\backends\utils.py", line 105, in _execute
    return self.cursor.execute(sql, params)
           ^^^^^^^^^^^^^^^^^^^^^^^^^^^^^^^^
psycopg2.errors.UndefinedTable: ОШИБКА:  отношение "Mamma_Mia_ingredient" не существует
LINE 1: ...redient"."id", "Mamma_Mia_ingredient"."name" FROM "Mamma_Mia...
                                                             ^


The above exception was the direct cause of the following exception:

Traceback (most recent call last):
  File "C:\Users\holmi\PycharmProjects\djangoProject\.venv\Lib\site-packages\django\core\handlers\exception.py", line 55, in inner
    response = get_response(request)
               ^^^^^^^^^^^^^^^^^^^^^
  File "C:\Users\holmi\PycharmProjects\djangoProject\.venv\Lib\site-packages\django\core\handlers\base.py", line 197, in _get_response
    response = wrapped_callback(request, *callback_args, **callback_kwargs)
               ^^^^^^^^^^^^^^^^^^^^^^^^^^^^^^^^^^^^^^^^^^^^^^^^^^^^^^^^^^^^
  File "C:\Users\holmi\PycharmProjects\djangoProject\.venv\Lib\site-packages\django\views\decorators\csrf.py", line 65, in _view_wrapper
    return view_func(request, *args, **kwargs)
           ^^^^^^^^^^^^^^^^^^^^^^^^^^^^^^^^^^^
  File "C:\Users\holmi\PycharmProjects\djangoProject\.venv\Lib\site-packages\django\views\generic\base.py", line 104, in view
    return self.dispatch(request, *args, **kwargs)
           ^^^^^^^^^^^^^^^^^^^^^^^^^^^^^^^^^^^^^^^
  File "C:\Users\holmi\PycharmProjects\djangoProject\.venv\Lib\site-packages\rest_framework\views.py", line 509, in dispatch
    response = self.handle_exception(exc)
               ^^^^^^^^^^^^^^^^^^^^^^^^^^
  File "C:\Users\holmi\PycharmProjects\djangoProject\.venv\Lib\site-packages\rest_framework\views.py", line 469, in handle_exception
    self.raise_uncaught_exception(exc)
  File "C:\Users\holmi\PycharmProjects\djangoProject\.venv\Lib\site-packages\rest_framework\views.py", line 480, in raise_uncaught_exception
    raise exc
  File "C:\Users\holmi\PycharmProjects\djangoProject\.venv\Lib\site-packages\rest_framework\views.py", line 506, in dispatch
    response = handler(request, *args, **kwargs)
               ^^^^^^^^^^^^^^^^^^^^^^^^^^^^^^^^^
  File "C:\Users\holmi\PycharmProjects\djangoProject\.venv\Lib\site-packages\rest_framework\generics.py", line 239, in get
    return self.list(request, *args, **kwargs)
           ^^^^^^^^^^^^^^^^^^^^^^^^^^^^^^^^^^^
  File "C:\Users\holmi\PycharmProjects\djangoProject\.venv\Lib\site-packages\rest_framework\mixins.py", line 46, in list
    return Response(serializer.data)
                    ^^^^^^^^^^^^^^^
  File "C:\Users\holmi\PycharmProjects\djangoProject\.venv\Lib\site-packages\rest_framework\serializers.py", line 768, in data
    ret = super().data
          ^^^^^^^^^^^^
  File "C:\Users\holmi\PycharmProjects\djangoProject\.venv\Lib\site-packages\rest_framework\serializers.py", line 253, in data
    self._data = self.to_representation(self.instance)
                 ^^^^^^^^^^^^^^^^^^^^^^^^^^^^^^^^^^^^^
  File "C:\Users\holmi\PycharmProjects\djangoProject\.venv\Lib\site-packages\rest_framework\serializers.py", line 686, in to_representation
    return [
           ^
  File "C:\Users\holmi\PycharmProjects\djangoProject\.venv\Lib\site-packages\django\db\models\query.py", line 400, in __iter__
    self._fetch_all()
  File "C:\Users\holmi\PycharmProjects\djangoProject\.venv\Lib\site-packages\django\db\models\query.py", line 1928, in _fetch_all
    self._result_cache = list(self._iterable_class(self))
                         ^^^^^^^^^^^^^^^^^^^^^^^^^^^^^^^^
  File "C:\Users\holmi\PycharmProjects\djangoProject\.venv\Lib\site-packages\django\db\models\query.py", line 91, in __iter__
    results = compiler.execute_sql(
              ^^^^^^^^^^^^^^^^^^^^^
  File "C:\Users\holmi\PycharmProjects\djangoProject\.venv\Lib\site-packages\django\db\models\sql\compiler.py", line 1562, in execute_sql
    cursor.execute(sql, params)
  File "C:\Users\holmi\PycharmProjects\djangoProject\.venv\Lib\site-packages\django\db\backends\utils.py", line 122, in execute
    return super().execute(sql, params)
           ^^^^^^^^^^^^^^^^^^^^^^^^^^^^
  File "C:\Users\holmi\PycharmProjects\djangoProject\.venv\Lib\site-packages\django\db\backends\utils.py", line 79, in execute
    return self._execute_with_wrappers(
           ^^^^^^^^^^^^^^^^^^^^^^^^^^^^
  File "C:\Users\holmi\PycharmProjects\djangoProject\.venv\Lib\site-packages\django\db\backends\utils.py", line 92, in _execute_with_wrappers
    return executor(sql, params, many, context)
           ^^^^^^^^^^^^^^^^^^^^^^^^^^^^^^^^^^^^
  File "C:\Users\holmi\PycharmProjects\djangoProject\.venv\Lib\site-packages\django\db\backends\utils.py", line 100, in _execute
    with self.db.wrap_database_errors:
  File "C:\Users\holmi\PycharmProjects\djangoProject\.venv\Lib\site-packages\django\db\utils.py", line 91, in __exit__
    raise dj_exc_value.with_traceback(traceback) from exc_value
  File "C:\Users\holmi\PycharmProjects\djangoProject\.venv\Lib\site-packages\django\db\backends\utils.py", line 105, in _execute
    return self.cursor.execute(sql, params)
           ^^^^^^^^^^^^^^^^^^^^^^^^^^^^^^^^
django.db.utils.ProgrammingError: ОШИБКА:  отношение "Mamma_Mia_ingredient" не существует
LINE 1: ...redient"."id", "Mamma_Mia_ingredient"."name" FROM "Mamma_Mia...
                                                             ^

Watching for file changes with StatReloader
Watching for file changes with StatReloader
Watching for file changes with StatReloader
Watching for file changes with StatReloader
C:\Users\holmi\PycharmProjects\djangoProject\Mamma_Mia\views.py changed, reloading.
Watching for file changes with StatReloader
Watching for file changes with StatReloader
Watching for file changes with StatReloader
Watching for file changes with StatReloader
Watching for file changes with StatReloader
C:\Users\holmi\PycharmProjects\djangoProject\Mamma_Mia\urls.py changed, reloading.
Watching for file changes with StatReloader
Watching for file changes with StatReloader
run server
Not Found: /'ingredients/49/delete/
Method Not Allowed: /ingredients/49/delete/
Not Found: /ingredients/49/delete/
run server
run server
C:\Users\holmi\PycharmProjects\djangoProject\Mamma_Mia\views.py changed, reloading.
Watching for file changes with StatReloader
Watching for file changes with StatReloader
Internal Server Error: /ingredients/create/
Traceback (most recent call last):
  File "C:\Users\holmi\PycharmProjects\djangoProject\.venv\Lib\site-packages\rest_framework\request.py", line 416, in __getattr__
    return getattr(self._request, attr)
           ^^^^^^^^^^^^^^^^^^^^^^^^^^^^
AttributeError: 'WSGIRequest' object has no attribute 'name'

During handling of the above exception, another exception occurred:

Traceback (most recent call last):
  File "C:\Users\holmi\PycharmProjects\djangoProject\.venv\Lib\site-packages\django\core\handlers\exception.py", line 55, in inner
    response = get_response(request)
               ^^^^^^^^^^^^^^^^^^^^^
  File "C:\Users\holmi\PycharmProjects\djangoProject\.venv\Lib\site-packages\django\core\handlers\base.py", line 197, in _get_response
    response = wrapped_callback(request, *callback_args, **callback_kwargs)
               ^^^^^^^^^^^^^^^^^^^^^^^^^^^^^^^^^^^^^^^^^^^^^^^^^^^^^^^^^^^^
  File "C:\Users\holmi\PycharmProjects\djangoProject\.venv\Lib\site-packages\django\views\decorators\csrf.py", line 65, in _view_wrapper
    return view_func(request, *args, **kwargs)
           ^^^^^^^^^^^^^^^^^^^^^^^^^^^^^^^^^^^
  File "C:\Users\holmi\PycharmProjects\djangoProject\.venv\Lib\site-packages\rest_framework\viewsets.py", line 125, in view
    return self.dispatch(request, *args, **kwargs)
           ^^^^^^^^^^^^^^^^^^^^^^^^^^^^^^^^^^^^^^^
  File "C:\Users\holmi\PycharmProjects\djangoProject\.venv\Lib\site-packages\rest_framework\views.py", line 509, in dispatch
    response = self.handle_exception(exc)
               ^^^^^^^^^^^^^^^^^^^^^^^^^^
  File "C:\Users\holmi\PycharmProjects\djangoProject\.venv\Lib\site-packages\rest_framework\views.py", line 469, in handle_exception
    self.raise_uncaught_exception(exc)
  File "C:\Users\holmi\PycharmProjects\djangoProject\.venv\Lib\site-packages\rest_framework\views.py", line 480, in raise_uncaught_exception
    raise exc
  File "C:\Users\holmi\PycharmProjects\djangoProject\.venv\Lib\site-packages\rest_framework\views.py", line 506, in dispatch
    response = handler(request, *args, **kwargs)
               ^^^^^^^^^^^^^^^^^^^^^^^^^^^^^^^^^
  File "C:\Users\holmi\PycharmProjects\djangoProject\Mamma_Mia\views.py", line 31, in create
    logging.info('Creating a new Ingredient' + str(request.name))
                                                   ^^^^^^^^^^^^
  File "C:\Users\holmi\PycharmProjects\djangoProject\.venv\Lib\site-packages\rest_framework\request.py", line 418, in __getattr__
    return self.__getattribute__(attr)
           ^^^^^^^^^^^^^^^^^^^^^^^^^^^
AttributeError: 'Request' object has no attribute 'name'
Internal Server Error: /ingredients/create/
Traceback (most recent call last):
  File "C:\Users\holmi\PycharmProjects\djangoProject\.venv\Lib\site-packages\rest_framework\request.py", line 416, in __getattr__
    return getattr(self._request, attr)
           ^^^^^^^^^^^^^^^^^^^^^^^^^^^^
AttributeError: 'WSGIRequest' object has no attribute 'name'

During handling of the above exception, another exception occurred:

Traceback (most recent call last):
  File "C:\Users\holmi\PycharmProjects\djangoProject\.venv\Lib\site-packages\django\core\handlers\exception.py", line 55, in inner
    response = get_response(request)
               ^^^^^^^^^^^^^^^^^^^^^
  File "C:\Users\holmi\PycharmProjects\djangoProject\.venv\Lib\site-packages\django\core\handlers\base.py", line 197, in _get_response
    response = wrapped_callback(request, *callback_args, **callback_kwargs)
               ^^^^^^^^^^^^^^^^^^^^^^^^^^^^^^^^^^^^^^^^^^^^^^^^^^^^^^^^^^^^
  File "C:\Users\holmi\PycharmProjects\djangoProject\.venv\Lib\site-packages\django\views\decorators\csrf.py", line 65, in _view_wrapper
    return view_func(request, *args, **kwargs)
           ^^^^^^^^^^^^^^^^^^^^^^^^^^^^^^^^^^^
  File "C:\Users\holmi\PycharmProjects\djangoProject\.venv\Lib\site-packages\rest_framework\viewsets.py", line 125, in view
    return self.dispatch(request, *args, **kwargs)
           ^^^^^^^^^^^^^^^^^^^^^^^^^^^^^^^^^^^^^^^
  File "C:\Users\holmi\PycharmProjects\djangoProject\.venv\Lib\site-packages\rest_framework\views.py", line 509, in dispatch
    response = self.handle_exception(exc)
               ^^^^^^^^^^^^^^^^^^^^^^^^^^
  File "C:\Users\holmi\PycharmProjects\djangoProject\.venv\Lib\site-packages\rest_framework\views.py", line 469, in handle_exception
    self.raise_uncaught_exception(exc)
  File "C:\Users\holmi\PycharmProjects\djangoProject\.venv\Lib\site-packages\rest_framework\views.py", line 480, in raise_uncaught_exception
    raise exc
  File "C:\Users\holmi\PycharmProjects\djangoProject\.venv\Lib\site-packages\rest_framework\views.py", line 506, in dispatch
    response = handler(request, *args, **kwargs)
               ^^^^^^^^^^^^^^^^^^^^^^^^^^^^^^^^^
  File "C:\Users\holmi\PycharmProjects\djangoProject\Mamma_Mia\views.py", line 31, in create
    logging.info('Creating a new Ingredient' + str(request.name))
                                                   ^^^^^^^^^^^^
  File "C:\Users\holmi\PycharmProjects\djangoProject\.venv\Lib\site-packages\rest_framework\request.py", line 418, in __getattr__
    return self.__getattribute__(attr)
           ^^^^^^^^^^^^^^^^^^^^^^^^^^^
AttributeError: 'Request' object has no attribute 'name'
C:\Users\holmi\PycharmProjects\djangoProject\Mamma_Mia\views.py changed, reloading.
Watching for file changes with StatReloader
Watching for file changes with StatReloader
run server
Not Found: /ingredients/cdc
C:\Users\holmi\PycharmProjects\djangoProject\Mamma_Mia\views.py changed, reloading.
Watching for file changes with StatReloader
Created ingredient 50: {'id': 50, 'name': 'new_ingridient'}
Deleted ingredient None
C:\Users\holmi\PycharmProjects\djangoProject\Mamma_Mia\views.py changed, reloading.
Watching for file changes with StatReloader
Not Found: /ingredients/45/delete/
Not Found: /ingredients/45/delett/
Not Found: /ingredients/45/delet/
Not Found: /ingredients/45/delete/
Not Found: /ingredients/45/delete/
Deleted ingredient None
Watching for file changes with StatReloader
Deleted ingredient Ingredient object (None)
Watching for file changes with StatReloader
Deleted ingredient None
C:\Users\holmi\PycharmProjects\djangoProject\Mamma_Mia\views.py changed, reloading.
Watching for file changes with StatReloader
Watching for file changes with StatReloader
run server
Not Found: /ingredients/45/
Created ingredient 51: {'id': 51, 'name': 'new_ingridient'}
Deleted ingredient None
Watching for file changes with StatReloader
Error deleting ingredient: 'NoneType' object has no attribute 'delete'
Bad Request: /ingredients/24/delete/
Error deleting ingredient: 'NoneType' object has no attribute 'delete'
Bad Request: /ingredients/5/delete/
Watching for file changes with StatReloader
Error deleting ingredient: 'dict' object has no attribute 'delete'
Bad Request: /ingredients/34/delete/
Watching for file changes with StatReloader
Deleted ingredient None
Watching for file changes with StatReloader
Created ingredient 52: {'id': 52, 'name': 'new_ingridient'}
Not Found: /ingredients/creat
Not Found: /ingredients/35/delete/
Deleted ingredient None
Watching for file changes with StatReloader
run server
Not Found: /ingredients/12/
Forbidden (CSRF cookie not set.): /
Created ingredient 53: {'id': 53, 'name': 'cocos'}
Deleted ingredient None
Not Found: /ingredients/4145/delete/
Not Found: /ingredients/create/2
Internal Server Error: /pizzas/create/
Traceback (most recent call last):
  File "C:\Users\holmi\PycharmProjects\djangoProject\.venv\Lib\site-packages\rest_framework\request.py", line 416, in __getattr__
    return getattr(self._request, attr)
           ^^^^^^^^^^^^^^^^^^^^^^^^^^^^
AttributeError: 'WSGIRequest' object has no attribute 'name'

During handling of the above exception, another exception occurred:

Traceback (most recent call last):
  File "C:\Users\holmi\PycharmProjects\djangoProject\.venv\Lib\site-packages\django\core\handlers\exception.py", line 55, in inner
    response = get_response(request)
               ^^^^^^^^^^^^^^^^^^^^^
  File "C:\Users\holmi\PycharmProjects\djangoProject\.venv\Lib\site-packages\django\core\handlers\base.py", line 197, in _get_response
    response = wrapped_callback(request, *callback_args, **callback_kwargs)
               ^^^^^^^^^^^^^^^^^^^^^^^^^^^^^^^^^^^^^^^^^^^^^^^^^^^^^^^^^^^^
  File "C:\Users\holmi\PycharmProjects\djangoProject\.venv\Lib\site-packages\django\views\decorators\csrf.py", line 65, in _view_wrapper
    return view_func(request, *args, **kwargs)
           ^^^^^^^^^^^^^^^^^^^^^^^^^^^^^^^^^^^
  File "C:\Users\holmi\PycharmProjects\djangoProject\.venv\Lib\site-packages\rest_framework\viewsets.py", line 125, in view
    return self.dispatch(request, *args, **kwargs)
           ^^^^^^^^^^^^^^^^^^^^^^^^^^^^^^^^^^^^^^^
  File "C:\Users\holmi\PycharmProjects\djangoProject\.venv\Lib\site-packages\rest_framework\views.py", line 509, in dispatch
    response = self.handle_exception(exc)
               ^^^^^^^^^^^^^^^^^^^^^^^^^^
  File "C:\Users\holmi\PycharmProjects\djangoProject\.venv\Lib\site-packages\rest_framework\views.py", line 469, in handle_exception
    self.raise_uncaught_exception(exc)
  File "C:\Users\holmi\PycharmProjects\djangoProject\.venv\Lib\site-packages\rest_framework\views.py", line 480, in raise_uncaught_exception
    raise exc
  File "C:\Users\holmi\PycharmProjects\djangoProject\.venv\Lib\site-packages\rest_framework\views.py", line 506, in dispatch
    response = handler(request, *args, **kwargs)
               ^^^^^^^^^^^^^^^^^^^^^^^^^^^^^^^^^
  File "C:\Users\holmi\PycharmProjects\djangoProject\Mamma_Mia\views.py", line 64, in create
    logging.info('Creating a new pizza...' + str(request.name))
                                                 ^^^^^^^^^^^^
  File "C:\Users\holmi\PycharmProjects\djangoProject\.venv\Lib\site-packages\rest_framework\request.py", line 418, in __getattr__
    return self.__getattribute__(attr)
           ^^^^^^^^^^^^^^^^^^^^^^^^^^^
AttributeError: 'Request' object has no attribute 'name'
C:\Users\holmi\PycharmProjects\djangoProject\Mamma_Mia\views.py changed, reloading.
Watching for file changes with StatReloader
Watching for file changes with StatReloader
Method Not Allowed: /pizzas/
run server
run server
Watching for file changes with StatReloader
Created pizza 1: {'id': 1, 'name': 'Margherita', 'description': 'Classic Italian pizza with tomato sauce, mozzarella cheese, and fresh basil.', 'price': '9.99', 'size': 'Medium', 'category': 'Vegetarian', 'dough_type': 'Traditional', 'ingredients': [1, 3, 5]}
Created pizza 2: {'id': 2, 'name': 'Margherita', 'description': 'Classic Italian pizza with tomato sauce, mozzarella cheese, and fresh basil.', 'price': '9.99', 'size': 'Medium', 'category': 'Vegetarian', 'dough_type': 'Traditional', 'ingredients': [1, 3, 5]}
Not Found: /pizzas/1
Not Found: /pizzas/1/
Method Not Allowed: /pizzas/2/delete/
Deleted pizza None
Not Found: /pizza/2/
Error updateing pizza: {'description': [ErrorDetail(string='This field is required.', code='required')], 'price': [ErrorDetail(string='This field is required.', code='required')], 'size': [ErrorDetail(string='This field is required.', code='required')], 'ingredients': [ErrorDetail(string='This field is required.', code='required')]}
Bad Request: /pizzas/1/update/
Watching for file changes with StatReloader
Internal Server Error: /pizzas/1/update/
Traceback (most recent call last):
  File "C:\Users\holmi\PycharmProjects\djangoProject\.venv\Lib\site-packages\django\core\handlers\exception.py", line 55, in inner
    response = get_response(request)
               ^^^^^^^^^^^^^^^^^^^^^
  File "C:\Users\holmi\PycharmProjects\djangoProject\.venv\Lib\site-packages\django\core\handlers\base.py", line 197, in _get_response
    response = wrapped_callback(request, *callback_args, **callback_kwargs)
               ^^^^^^^^^^^^^^^^^^^^^^^^^^^^^^^^^^^^^^^^^^^^^^^^^^^^^^^^^^^^
  File "C:\Users\holmi\PycharmProjects\djangoProject\.venv\Lib\site-packages\django\views\decorators\csrf.py", line 65, in _view_wrapper
    return view_func(request, *args, **kwargs)
           ^^^^^^^^^^^^^^^^^^^^^^^^^^^^^^^^^^^
  File "C:\Users\holmi\PycharmProjects\djangoProject\.venv\Lib\site-packages\rest_framework\viewsets.py", line 125, in view
    return self.dispatch(request, *args, **kwargs)
           ^^^^^^^^^^^^^^^^^^^^^^^^^^^^^^^^^^^^^^^
  File "C:\Users\holmi\PycharmProjects\djangoProject\.venv\Lib\site-packages\rest_framework\views.py", line 509, in dispatch
    response = self.handle_exception(exc)
               ^^^^^^^^^^^^^^^^^^^^^^^^^^
  File "C:\Users\holmi\PycharmProjects\djangoProject\.venv\Lib\site-packages\rest_framework\views.py", line 469, in handle_exception
    self.raise_uncaught_exception(exc)
  File "C:\Users\holmi\PycharmProjects\djangoProject\.venv\Lib\site-packages\rest_framework\views.py", line 480, in raise_uncaught_exception
    raise exc
  File "C:\Users\holmi\PycharmProjects\djangoProject\.venv\Lib\site-packages\rest_framework\views.py", line 506, in dispatch
    response = handler(request, *args, **kwargs)
               ^^^^^^^^^^^^^^^^^^^^^^^^^^^^^^^^^
  File "C:\Users\holmi\PycharmProjects\djangoProject\Mamma_Mia\views.py", line 79, in update
    return self.perform_action('update', instance=instance, data=request.data, partial=partial)
           ^^^^^^^^^^^^^^^^^^^^^^^^^^^^^^^^^^^^^^^^^^^^^^^^^^^^^^^^^^^^^^^^^^^^^^^^^^^^^^^^^^^^
TypeError: PizzaViewSet.perform_action() got an unexpected keyword argument 'partial'
Watching for file changes with StatReloader
Updated pizza 1: {'id': 1, 'name': 'Peperonni', 'description': 'Classic Italian pizza with tomato sauce, mozzarella cheese, and fresh basil.', 'price': '9.99', 'size': 'Medium', 'category': 'Meat', 'dough_type': 'Traditional', 'ingredients': [1, 3, 5]}
Not Found: /pizzas/4/update/
Not Found: /pizzas/4/update/
Bad Request: /pizzas/1/update/
C:\Users\holmi\PycharmProjects\djangoProject\Mamma_Mia\models.py changed, reloading.
Watching for file changes with StatReloader
C:\Users\holmi\PycharmProjects\djangoProject\Mamma_Mia\views.py changed, reloading.
Watching for file changes with StatReloader
Watching for file changes with StatReloader
Method Not Allowed: /toppings/create/
Method Not Allowed: /toppings/create/
Created topping 10: {'id': 10, 'name': 'Perfect_Cheese', 'price': '10.00'}
Method Not Allowed: /toppings/1/delete/
Method Not Allowed: /toppings/1/delete/
Deleted topping None
Watching for file changes with StatReloader
Not Found: /toppings/1/update/
Updated topping 2: {'id': 2, 'name': 'Sesame oil', 'price': '4.00'}
Updated topping 2: {'id': 2, 'name': 'second_topping', 'price': '4.00'}
2024-03-07 03:35:58,055 - INFO - Watching for file changes with StatReloader
2024-03-07 03:49:31,266 - INFO - Watching for file changes with StatReloader
2024-03-07 03:57:13,703 - INFO - C:\Users\holmi\PycharmProjects\djangoProject\djangoProject\urls.py changed, reloading.
2024-03-07 03:57:14,589 - INFO - Watching for file changes with StatReloader
2024-03-07 03:58:32,373 - INFO - C:\Users\holmi\PycharmProjects\djangoProject\djangoProject\urls.py changed, reloading.
2024-03-07 03:58:33,237 - INFO - Watching for file changes with StatReloader
2024-03-07 03:59:47,533 - INFO - C:\Users\holmi\PycharmProjects\djangoProject\Mamma_Mia\views.py changed, reloading.
2024-03-07 03:59:48,355 - INFO - Watching for file changes with StatReloader
2024-03-07 04:01:50,716 - INFO - C:\Users\holmi\PycharmProjects\djangoProject\Mamma_Mia\views.py changed, reloading.
2024-03-07 04:01:51,468 - INFO - Watching for file changes with StatReloader
2024-03-07 04:05:25,967 - INFO - C:\Users\holmi\PycharmProjects\djangoProject\Mamma_Mia\views.py changed, reloading.
2024-03-07 04:05:27,187 - INFO - Watching for file changes with StatReloader
2024-03-07 04:12:01,942 - INFO - Watching for file changes with StatReloader
2024-03-07 04:14:31,468 - INFO - Watching for file changes with StatReloader
2024-03-07 04:15:12,126 - WARNING - Method Not Allowed: /auth/sign-up/customer/
2024-03-07 04:15:18,599 - WARNING - Bad Request: /auth/sign-up/customer/
2024-03-07 04:18:46,633 - WARNING - Bad Request: /auth/sign-up/customer/
2024-03-07 04:19:22,703 - WARNING - Not Found: /auth/sign-ip/customer/
2024-03-07 04:19:34,647 - WARNING - Not Found: /auth/sign-ip/customer/
2024-03-07 04:21:17,563 - WARNING - Bad Request: /auth/sign-in/customer/
2024-03-07 04:21:51,891 - WARNING - Bad Request: /auth/sign-in/customer/
2024-03-07 04:26:35,616 - INFO - Watching for file changes with StatReloader
2024-03-07 04:26:57,921 - WARNING - Bad Request: /auth/sign-in/customer/
2024-03-07 04:27:06,956 - WARNING - Bad Request: /auth/sign-in/customer/
2024-03-07 04:27:46,435 - WARNING - Bad Request: /auth/sign-in/customer/
2024-03-07 04:27:50,024 - WARNING - Bad Request: /auth/sign-in/customer/
2024-03-07 04:28:02,733 - WARNING - Unauthorized: /auth/sign-in/customer/
2024-03-07 04:30:29,615 - WARNING - Not Found: /auth/sign-un/customer/
2024-03-07 04:31:13,557 - WARNING - Bad Request: /auth/sign-up/customer/
2024-03-07 04:31:58,658 - WARNING - Bad Request: /auth/sign-up/customer/
2024-03-07 04:33:05,539 - INFO - Watching for file changes with StatReloader
2024-03-07 04:33:10,520 - WARNING - Bad Request: /auth/sign-up/customer/
2024-03-07 04:33:36,826 - WARNING - Not Found: /auth/sign-ip/customer/
2024-03-07 04:33:43,356 - WARNING - Not Found: /auth/sign-ip/customer/
2024-03-07 04:34:16,760 - WARNING - Not Found: /auth/sign-ip/customer/
2024-03-07 04:34:27,854 - WARNING - Bad Request: /auth/sign-up/customer/
2024-03-07 04:36:47,145 - INFO - Watching for file changes with StatReloader
2024-03-07 04:37:02,173 - ERROR - Internal Server Error: /customers
Traceback (most recent call last):
  File "C:\Users\holmi\PycharmProjects\djangoProject\.venv\Lib\site-packages\django\core\handlers\exception.py", line 55, in inner
    response = get_response(request)
               ^^^^^^^^^^^^^^^^^^^^^
  File "C:\Users\holmi\PycharmProjects\djangoProject\.venv\Lib\site-packages\django\utils\deprecation.py", line 136, in __call__
    response = self.process_response(request, response)
               ^^^^^^^^^^^^^^^^^^^^^^^^^^^^^^^^^^^^^^^^
  File "C:\Users\holmi\PycharmProjects\djangoProject\.venv\Lib\site-packages\django\middleware\common.py", line 108, in process_response
    return self.response_redirect_class(self.get_full_path_with_slash(request))
                                        ^^^^^^^^^^^^^^^^^^^^^^^^^^^^^^^^^^^^^^
  File "C:\Users\holmi\PycharmProjects\djangoProject\.venv\Lib\site-packages\django\middleware\common.py", line 87, in get_full_path_with_slash
    raise RuntimeError(
RuntimeError: You called this URL via POST, but the URL doesn't end in a slash and you have APPEND_SLASH set. Django can't redirect to the slash URL while maintaining POST data. Change your form to point to localhost:8000/customers/ (note the trailing slash), or set APPEND_SLASH=False in your Django settings.
2024-03-07 04:37:03,716 - ERROR - Internal Server Error: /customers
Traceback (most recent call last):
  File "C:\Users\holmi\PycharmProjects\djangoProject\.venv\Lib\site-packages\django\core\handlers\exception.py", line 55, in inner
    response = get_response(request)
               ^^^^^^^^^^^^^^^^^^^^^
  File "C:\Users\holmi\PycharmProjects\djangoProject\.venv\Lib\site-packages\django\utils\deprecation.py", line 136, in __call__
    response = self.process_response(request, response)
               ^^^^^^^^^^^^^^^^^^^^^^^^^^^^^^^^^^^^^^^^
  File "C:\Users\holmi\PycharmProjects\djangoProject\.venv\Lib\site-packages\django\middleware\common.py", line 108, in process_response
    return self.response_redirect_class(self.get_full_path_with_slash(request))
                                        ^^^^^^^^^^^^^^^^^^^^^^^^^^^^^^^^^^^^^^
  File "C:\Users\holmi\PycharmProjects\djangoProject\.venv\Lib\site-packages\django\middleware\common.py", line 87, in get_full_path_with_slash
    raise RuntimeError(
RuntimeError: You called this URL via POST, but the URL doesn't end in a slash and you have APPEND_SLASH set. Django can't redirect to the slash URL while maintaining POST data. Change your form to point to localhost:8000/customers/ (note the trailing slash), or set APPEND_SLASH=False in your Django settings.
2024-03-07 04:37:21,499 - WARNING - Method Not Allowed: /customers/
2024-03-07 04:38:48,792 - INFO - C:\Users\holmi\PycharmProjects\djangoProject\Mamma_Mia\models.py changed, reloading.
2024-03-07 04:38:49,658 - INFO - Watching for file changes with StatReloader
2024-03-07 04:46:00,413 - INFO - C:\Users\holmi\PycharmProjects\djangoProject\Mamma_Mia\views.py changed, reloading.
2024-03-07 04:46:01,127 - INFO - Watching for file changes with StatReloader
2024-03-07 04:46:43,102 - INFO - Watching for file changes with StatReloader
2024-03-07 04:47:02,481 - INFO - Watching for file changes with StatReloader
2024-03-07 04:48:49,433 - WARNING - Method Not Allowed: /auth/sign-up/customer/
2024-03-07 04:48:54,795 - WARNING - Bad Request: /auth/sign-up/customer/
2024-03-07 04:50:06,014 - ERROR - Internal Server Error: /auth/sign-up/customer/
Traceback (most recent call last):
  File "C:\Users\holmi\PycharmProjects\djangoProject\.venv\Lib\site-packages\django\core\handlers\exception.py", line 55, in inner
    response = get_response(request)
               ^^^^^^^^^^^^^^^^^^^^^
  File "C:\Users\holmi\PycharmProjects\djangoProject\.venv\Lib\site-packages\django\core\handlers\base.py", line 197, in _get_response
    response = wrapped_callback(request, *callback_args, **callback_kwargs)
               ^^^^^^^^^^^^^^^^^^^^^^^^^^^^^^^^^^^^^^^^^^^^^^^^^^^^^^^^^^^^
  File "C:\Users\holmi\PycharmProjects\djangoProject\.venv\Lib\site-packages\django\views\decorators\csrf.py", line 65, in _view_wrapper
    return view_func(request, *args, **kwargs)
           ^^^^^^^^^^^^^^^^^^^^^^^^^^^^^^^^^^^
  File "C:\Users\holmi\PycharmProjects\djangoProject\.venv\Lib\site-packages\django\views\generic\base.py", line 104, in view
    return self.dispatch(request, *args, **kwargs)
           ^^^^^^^^^^^^^^^^^^^^^^^^^^^^^^^^^^^^^^^
  File "C:\Users\holmi\PycharmProjects\djangoProject\.venv\Lib\site-packages\rest_framework\views.py", line 509, in dispatch
    response = self.handle_exception(exc)
               ^^^^^^^^^^^^^^^^^^^^^^^^^^
  File "C:\Users\holmi\PycharmProjects\djangoProject\.venv\Lib\site-packages\rest_framework\views.py", line 469, in handle_exception
    self.raise_uncaught_exception(exc)
  File "C:\Users\holmi\PycharmProjects\djangoProject\.venv\Lib\site-packages\rest_framework\views.py", line 480, in raise_uncaught_exception
    raise exc
  File "C:\Users\holmi\PycharmProjects\djangoProject\.venv\Lib\site-packages\rest_framework\views.py", line 506, in dispatch
    response = handler(request, *args, **kwargs)
               ^^^^^^^^^^^^^^^^^^^^^^^^^^^^^^^^^
  File "C:\Users\holmi\PycharmProjects\djangoProject\.venv\Lib\site-packages\rest_framework\decorators.py", line 50, in handler
    return func(*args, **kwargs)
           ^^^^^^^^^^^^^^^^^^^^^
  File "C:\Users\holmi\PycharmProjects\djangoProject\Mamma_Mia\views.py", line 20, in create_customer
    customer = serializer.save()
               ^^^^^^^^^^^^^^^^^
  File "C:\Users\holmi\PycharmProjects\djangoProject\.venv\Lib\site-packages\rest_framework\serializers.py", line 212, in save
    self.instance = self.create(validated_data)
                    ^^^^^^^^^^^^^^^^^^^^^^^^^^^
  File "C:\Users\holmi\PycharmProjects\djangoProject\Mamma_Mia\serializer.py", line 42, in create
    customer = Customer.objects.create_user(**validated_data)
               ^^^^^^^^^^^^^^^^^^^^^^^^^^^^
AttributeError: 'Manager' object has no attribute 'create_user'
2024-03-07 04:53:46,393 - INFO - Watching for file changes with StatReloader
2024-03-07 04:54:06,154 - ERROR - Internal Server Error: /auth/sign-up/customer/
Traceback (most recent call last):
  File "C:\Users\holmi\PycharmProjects\djangoProject\.venv\Lib\site-packages\django\core\handlers\exception.py", line 55, in inner
    response = get_response(request)
               ^^^^^^^^^^^^^^^^^^^^^
  File "C:\Users\holmi\PycharmProjects\djangoProject\.venv\Lib\site-packages\django\core\handlers\base.py", line 197, in _get_response
    response = wrapped_callback(request, *callback_args, **callback_kwargs)
               ^^^^^^^^^^^^^^^^^^^^^^^^^^^^^^^^^^^^^^^^^^^^^^^^^^^^^^^^^^^^
  File "C:\Users\holmi\PycharmProjects\djangoProject\.venv\Lib\site-packages\django\views\decorators\csrf.py", line 65, in _view_wrapper
    return view_func(request, *args, **kwargs)
           ^^^^^^^^^^^^^^^^^^^^^^^^^^^^^^^^^^^
  File "C:\Users\holmi\PycharmProjects\djangoProject\.venv\Lib\site-packages\django\views\generic\base.py", line 104, in view
    return self.dispatch(request, *args, **kwargs)
           ^^^^^^^^^^^^^^^^^^^^^^^^^^^^^^^^^^^^^^^
  File "C:\Users\holmi\PycharmProjects\djangoProject\.venv\Lib\site-packages\rest_framework\views.py", line 509, in dispatch
    response = self.handle_exception(exc)
               ^^^^^^^^^^^^^^^^^^^^^^^^^^
  File "C:\Users\holmi\PycharmProjects\djangoProject\.venv\Lib\site-packages\rest_framework\views.py", line 469, in handle_exception
    self.raise_uncaught_exception(exc)
  File "C:\Users\holmi\PycharmProjects\djangoProject\.venv\Lib\site-packages\rest_framework\views.py", line 480, in raise_uncaught_exception
    raise exc
  File "C:\Users\holmi\PycharmProjects\djangoProject\.venv\Lib\site-packages\rest_framework\views.py", line 506, in dispatch
    response = handler(request, *args, **kwargs)
               ^^^^^^^^^^^^^^^^^^^^^^^^^^^^^^^^^
  File "C:\Users\holmi\PycharmProjects\djangoProject\.venv\Lib\site-packages\rest_framework\decorators.py", line 50, in handler
    return func(*args, **kwargs)
           ^^^^^^^^^^^^^^^^^^^^^
  File "C:\Users\holmi\PycharmProjects\djangoProject\Mamma_Mia\views.py", line 20, in create_customer
    customer = serializer.save()
               ^^^^^^^^^^^^^^^^^
  File "C:\Users\holmi\PycharmProjects\djangoProject\.venv\Lib\site-packages\rest_framework\serializers.py", line 212, in save
    self.instance = self.create(validated_data)
                    ^^^^^^^^^^^^^^^^^^^^^^^^^^^
  File "C:\Users\holmi\PycharmProjects\djangoProject\Mamma_Mia\serializer.py", line 42, in create
    customer = Customer.objects.create_user(**validated_data)
               ^^^^^^^^^^^^^^^^^^^^^^^^^^^^
AttributeError: 'Manager' object has no attribute 'create_user'
2024-03-07 04:57:38,786 - INFO - Watching for file changes with StatReloader
2024-03-07 04:59:03,305 - INFO - Watching for file changes with StatReloader
2024-03-07 04:59:10,368 - ERROR - Internal Server Error: /auth/sign-up/customer/
Traceback (most recent call last):
  File "C:\Users\holmi\PycharmProjects\djangoProject\.venv\Lib\site-packages\django\db\backends\utils.py", line 105, in _execute
    return self.cursor.execute(sql, params)
           ^^^^^^^^^^^^^^^^^^^^^^^^^^^^^^^^
psycopg2.errors.UndefinedColumn: ОШИБКА:  столбец "last_login" в таблице "Mamma_Mia_customer" не существует
LINE 1: INSERT INTO "Mamma_Mia_customer" ("password", "last_login", ...
                                                      ^


The above exception was the direct cause of the following exception:

Traceback (most recent call last):
  File "C:\Users\holmi\PycharmProjects\djangoProject\.venv\Lib\site-packages\django\core\handlers\exception.py", line 55, in inner
    response = get_response(request)
               ^^^^^^^^^^^^^^^^^^^^^
  File "C:\Users\holmi\PycharmProjects\djangoProject\.venv\Lib\site-packages\django\core\handlers\base.py", line 197, in _get_response
    response = wrapped_callback(request, *callback_args, **callback_kwargs)
               ^^^^^^^^^^^^^^^^^^^^^^^^^^^^^^^^^^^^^^^^^^^^^^^^^^^^^^^^^^^^
  File "C:\Users\holmi\PycharmProjects\djangoProject\.venv\Lib\site-packages\django\views\decorators\csrf.py", line 65, in _view_wrapper
    return view_func(request, *args, **kwargs)
           ^^^^^^^^^^^^^^^^^^^^^^^^^^^^^^^^^^^
  File "C:\Users\holmi\PycharmProjects\djangoProject\.venv\Lib\site-packages\django\views\generic\base.py", line 104, in view
    return self.dispatch(request, *args, **kwargs)
           ^^^^^^^^^^^^^^^^^^^^^^^^^^^^^^^^^^^^^^^
  File "C:\Users\holmi\PycharmProjects\djangoProject\.venv\Lib\site-packages\rest_framework\views.py", line 509, in dispatch
    response = self.handle_exception(exc)
               ^^^^^^^^^^^^^^^^^^^^^^^^^^
  File "C:\Users\holmi\PycharmProjects\djangoProject\.venv\Lib\site-packages\rest_framework\views.py", line 469, in handle_exception
    self.raise_uncaught_exception(exc)
  File "C:\Users\holmi\PycharmProjects\djangoProject\.venv\Lib\site-packages\rest_framework\views.py", line 480, in raise_uncaught_exception
    raise exc
  File "C:\Users\holmi\PycharmProjects\djangoProject\.venv\Lib\site-packages\rest_framework\views.py", line 506, in dispatch
    response = handler(request, *args, **kwargs)
               ^^^^^^^^^^^^^^^^^^^^^^^^^^^^^^^^^
  File "C:\Users\holmi\PycharmProjects\djangoProject\.venv\Lib\site-packages\rest_framework\decorators.py", line 50, in handler
    return func(*args, **kwargs)
           ^^^^^^^^^^^^^^^^^^^^^
  File "C:\Users\holmi\PycharmProjects\djangoProject\Mamma_Mia\views.py", line 20, in create_customer
    customer = serializer.save()
               ^^^^^^^^^^^^^^^^^
  File "C:\Users\holmi\PycharmProjects\djangoProject\.venv\Lib\site-packages\rest_framework\serializers.py", line 212, in save
    self.instance = self.create(validated_data)
                    ^^^^^^^^^^^^^^^^^^^^^^^^^^^
  File "C:\Users\holmi\PycharmProjects\djangoProject\Mamma_Mia\serializer.py", line 42, in create
    customer = Customer.objects.create_user(**validated_data)
               ^^^^^^^^^^^^^^^^^^^^^^^^^^^^^^^^^^^^^^^^^^^^^^
  File "C:\Users\holmi\PycharmProjects\djangoProject\Mamma_Mia\models.py", line 17, in create_user
    user.save(using=self._db)
  File "C:\Users\holmi\PycharmProjects\djangoProject\.venv\Lib\site-packages\django\contrib\auth\base_user.py", line 78, in save
    super().save(*args, **kwargs)
  File "C:\Users\holmi\PycharmProjects\djangoProject\.venv\Lib\site-packages\django\db\models\base.py", line 822, in save
    self.save_base(
  File "C:\Users\holmi\PycharmProjects\djangoProject\.venv\Lib\site-packages\django\db\models\base.py", line 909, in save_base
    updated = self._save_table(
              ^^^^^^^^^^^^^^^^^
  File "C:\Users\holmi\PycharmProjects\djangoProject\.venv\Lib\site-packages\django\db\models\base.py", line 1067, in _save_table
    results = self._do_insert(
              ^^^^^^^^^^^^^^^^
  File "C:\Users\holmi\PycharmProjects\djangoProject\.venv\Lib\site-packages\django\db\models\base.py", line 1108, in _do_insert
    return manager._insert(
           ^^^^^^^^^^^^^^^^
  File "C:\Users\holmi\PycharmProjects\djangoProject\.venv\Lib\site-packages\django\db\models\manager.py", line 87, in manager_method
    return getattr(self.get_queryset(), name)(*args, **kwargs)
           ^^^^^^^^^^^^^^^^^^^^^^^^^^^^^^^^^^^^^^^^^^^^^^^^^^^
  File "C:\Users\holmi\PycharmProjects\djangoProject\.venv\Lib\site-packages\django\db\models\query.py", line 1847, in _insert
    return query.get_compiler(using=using).execute_sql(returning_fields)
           ^^^^^^^^^^^^^^^^^^^^^^^^^^^^^^^^^^^^^^^^^^^^^^^^^^^^^^^^^^^^^
  File "C:\Users\holmi\PycharmProjects\djangoProject\.venv\Lib\site-packages\django\db\models\sql\compiler.py", line 1823, in execute_sql
    cursor.execute(sql, params)
  File "C:\Users\holmi\PycharmProjects\djangoProject\.venv\Lib\site-packages\django\db\backends\utils.py", line 122, in execute
    return super().execute(sql, params)
           ^^^^^^^^^^^^^^^^^^^^^^^^^^^^
  File "C:\Users\holmi\PycharmProjects\djangoProject\.venv\Lib\site-packages\django\db\backends\utils.py", line 79, in execute
    return self._execute_with_wrappers(
           ^^^^^^^^^^^^^^^^^^^^^^^^^^^^
  File "C:\Users\holmi\PycharmProjects\djangoProject\.venv\Lib\site-packages\django\db\backends\utils.py", line 92, in _execute_with_wrappers
    return executor(sql, params, many, context)
           ^^^^^^^^^^^^^^^^^^^^^^^^^^^^^^^^^^^^
  File "C:\Users\holmi\PycharmProjects\djangoProject\.venv\Lib\site-packages\django\db\backends\utils.py", line 100, in _execute
    with self.db.wrap_database_errors:
  File "C:\Users\holmi\PycharmProjects\djangoProject\.venv\Lib\site-packages\django\db\utils.py", line 91, in __exit__
    raise dj_exc_value.with_traceback(traceback) from exc_value
  File "C:\Users\holmi\PycharmProjects\djangoProject\.venv\Lib\site-packages\django\db\backends\utils.py", line 105, in _execute
    return self.cursor.execute(sql, params)
           ^^^^^^^^^^^^^^^^^^^^^^^^^^^^^^^^
django.db.utils.ProgrammingError: ОШИБКА:  столбец "last_login" в таблице "Mamma_Mia_customer" не существует
LINE 1: INSERT INTO "Mamma_Mia_customer" ("password", "last_login", ...
                                                      ^

2024-03-07 05:00:36,249 - INFO - C:\Users\holmi\PycharmProjects\djangoProject\Mamma_Mia\models.py changed, reloading.
2024-03-07 05:00:36,909 - INFO - Watching for file changes with StatReloader
2024-03-07 05:01:18,427 - INFO - Watching for file changes with StatReloader
2024-03-07 05:01:48,634 - INFO - Watching for file changes with StatReloader
2024-03-07 05:01:53,513 - ERROR - Internal Server Error: /auth/sign-up/customer/
Traceback (most recent call last):
  File "C:\Users\holmi\PycharmProjects\djangoProject\.venv\Lib\site-packages\django\db\backends\utils.py", line 105, in _execute
    return self.cursor.execute(sql, params)
           ^^^^^^^^^^^^^^^^^^^^^^^^^^^^^^^^
psycopg2.errors.NotNullViolation: ОШИБКА:  значение NULL в столбце "age" отношения "Mamma_Mia_customer" нарушает ограничение NOT NULL
DETAIL:  Ошибочная строка содержит (1, user123, user123@example.com, pbkdf2_sha256$720000$29km70qcq8cjnrPUqcxc04$0jVi3zZSr+nEKrDNCgi/..., 2024-03-07 00:01:53.448845+00, null, t, f, null).


The above exception was the direct cause of the following exception:

Traceback (most recent call last):
  File "C:\Users\holmi\PycharmProjects\djangoProject\.venv\Lib\site-packages\django\core\handlers\exception.py", line 55, in inner
    response = get_response(request)
               ^^^^^^^^^^^^^^^^^^^^^
  File "C:\Users\holmi\PycharmProjects\djangoProject\.venv\Lib\site-packages\django\core\handlers\base.py", line 197, in _get_response
    response = wrapped_callback(request, *callback_args, **callback_kwargs)
               ^^^^^^^^^^^^^^^^^^^^^^^^^^^^^^^^^^^^^^^^^^^^^^^^^^^^^^^^^^^^
  File "C:\Users\holmi\PycharmProjects\djangoProject\.venv\Lib\site-packages\django\views\decorators\csrf.py", line 65, in _view_wrapper
    return view_func(request, *args, **kwargs)
           ^^^^^^^^^^^^^^^^^^^^^^^^^^^^^^^^^^^
  File "C:\Users\holmi\PycharmProjects\djangoProject\.venv\Lib\site-packages\django\views\generic\base.py", line 104, in view
    return self.dispatch(request, *args, **kwargs)
           ^^^^^^^^^^^^^^^^^^^^^^^^^^^^^^^^^^^^^^^
  File "C:\Users\holmi\PycharmProjects\djangoProject\.venv\Lib\site-packages\rest_framework\views.py", line 509, in dispatch
    response = self.handle_exception(exc)
               ^^^^^^^^^^^^^^^^^^^^^^^^^^
  File "C:\Users\holmi\PycharmProjects\djangoProject\.venv\Lib\site-packages\rest_framework\views.py", line 469, in handle_exception
    self.raise_uncaught_exception(exc)
  File "C:\Users\holmi\PycharmProjects\djangoProject\.venv\Lib\site-packages\rest_framework\views.py", line 480, in raise_uncaught_exception
    raise exc
  File "C:\Users\holmi\PycharmProjects\djangoProject\.venv\Lib\site-packages\rest_framework\views.py", line 506, in dispatch
    response = handler(request, *args, **kwargs)
               ^^^^^^^^^^^^^^^^^^^^^^^^^^^^^^^^^
  File "C:\Users\holmi\PycharmProjects\djangoProject\.venv\Lib\site-packages\rest_framework\decorators.py", line 50, in handler
    return func(*args, **kwargs)
           ^^^^^^^^^^^^^^^^^^^^^
  File "C:\Users\holmi\PycharmProjects\djangoProject\Mamma_Mia\views.py", line 20, in create_customer
    customer = serializer.save()
               ^^^^^^^^^^^^^^^^^
  File "C:\Users\holmi\PycharmProjects\djangoProject\.venv\Lib\site-packages\rest_framework\serializers.py", line 212, in save
    self.instance = self.create(validated_data)
                    ^^^^^^^^^^^^^^^^^^^^^^^^^^^
  File "C:\Users\holmi\PycharmProjects\djangoProject\Mamma_Mia\serializer.py", line 42, in create
    customer = Customer.objects.create_user(**validated_data)
               ^^^^^^^^^^^^^^^^^^^^^^^^^^^^^^^^^^^^^^^^^^^^^^
  File "C:\Users\holmi\PycharmProjects\djangoProject\Mamma_Mia\models.py", line 17, in create_user
    user.save(using=self._db)
  File "C:\Users\holmi\PycharmProjects\djangoProject\.venv\Lib\site-packages\django\contrib\auth\base_user.py", line 78, in save
    super().save(*args, **kwargs)
  File "C:\Users\holmi\PycharmProjects\djangoProject\.venv\Lib\site-packages\django\db\models\base.py", line 822, in save
    self.save_base(
  File "C:\Users\holmi\PycharmProjects\djangoProject\.venv\Lib\site-packages\django\db\models\base.py", line 909, in save_base
    updated = self._save_table(
              ^^^^^^^^^^^^^^^^^
  File "C:\Users\holmi\PycharmProjects\djangoProject\.venv\Lib\site-packages\django\db\models\base.py", line 1067, in _save_table
    results = self._do_insert(
              ^^^^^^^^^^^^^^^^
  File "C:\Users\holmi\PycharmProjects\djangoProject\.venv\Lib\site-packages\django\db\models\base.py", line 1108, in _do_insert
    return manager._insert(
           ^^^^^^^^^^^^^^^^
  File "C:\Users\holmi\PycharmProjects\djangoProject\.venv\Lib\site-packages\django\db\models\manager.py", line 87, in manager_method
    return getattr(self.get_queryset(), name)(*args, **kwargs)
           ^^^^^^^^^^^^^^^^^^^^^^^^^^^^^^^^^^^^^^^^^^^^^^^^^^^
  File "C:\Users\holmi\PycharmProjects\djangoProject\.venv\Lib\site-packages\django\db\models\query.py", line 1847, in _insert
    return query.get_compiler(using=using).execute_sql(returning_fields)
           ^^^^^^^^^^^^^^^^^^^^^^^^^^^^^^^^^^^^^^^^^^^^^^^^^^^^^^^^^^^^^
  File "C:\Users\holmi\PycharmProjects\djangoProject\.venv\Lib\site-packages\django\db\models\sql\compiler.py", line 1823, in execute_sql
    cursor.execute(sql, params)
  File "C:\Users\holmi\PycharmProjects\djangoProject\.venv\Lib\site-packages\django\db\backends\utils.py", line 122, in execute
    return super().execute(sql, params)
           ^^^^^^^^^^^^^^^^^^^^^^^^^^^^
  File "C:\Users\holmi\PycharmProjects\djangoProject\.venv\Lib\site-packages\django\db\backends\utils.py", line 79, in execute
    return self._execute_with_wrappers(
           ^^^^^^^^^^^^^^^^^^^^^^^^^^^^
  File "C:\Users\holmi\PycharmProjects\djangoProject\.venv\Lib\site-packages\django\db\backends\utils.py", line 92, in _execute_with_wrappers
    return executor(sql, params, many, context)
           ^^^^^^^^^^^^^^^^^^^^^^^^^^^^^^^^^^^^
  File "C:\Users\holmi\PycharmProjects\djangoProject\.venv\Lib\site-packages\django\db\backends\utils.py", line 100, in _execute
    with self.db.wrap_database_errors:
  File "C:\Users\holmi\PycharmProjects\djangoProject\.venv\Lib\site-packages\django\db\utils.py", line 91, in __exit__
    raise dj_exc_value.with_traceback(traceback) from exc_value
  File "C:\Users\holmi\PycharmProjects\djangoProject\.venv\Lib\site-packages\django\db\backends\utils.py", line 105, in _execute
    return self.cursor.execute(sql, params)
           ^^^^^^^^^^^^^^^^^^^^^^^^^^^^^^^^
django.db.utils.IntegrityError: ОШИБКА:  значение NULL в столбце "age" отношения "Mamma_Mia_customer" нарушает ограничение NOT NULL
DETAIL:  Ошибочная строка содержит (1, user123, user123@example.com, pbkdf2_sha256$720000$29km70qcq8cjnrPUqcxc04$0jVi3zZSr+nEKrDNCgi/..., 2024-03-07 00:01:53.448845+00, null, t, f, null).

2024-03-07 05:02:33,845 - ERROR - Internal Server Error: /auth/sign-up/customer/
Traceback (most recent call last):
  File "C:\Users\holmi\PycharmProjects\djangoProject\.venv\Lib\site-packages\django\db\backends\utils.py", line 105, in _execute
    return self.cursor.execute(sql, params)
           ^^^^^^^^^^^^^^^^^^^^^^^^^^^^^^^^
psycopg2.errors.NotNullViolation: ОШИБКА:  значение NULL в столбце "age" отношения "Mamma_Mia_customer" нарушает ограничение NOT NULL
DETAIL:  Ошибочная строка содержит (2, user123, user123@example.com, pbkdf2_sha256$720000$7m0BtyVEt3svOvetINJnSM$v9ok1PHIzAK3wCWmv+97..., 2024-03-07 00:02:33.773706+00, null, t, f, null).


The above exception was the direct cause of the following exception:

Traceback (most recent call last):
  File "C:\Users\holmi\PycharmProjects\djangoProject\.venv\Lib\site-packages\django\core\handlers\exception.py", line 55, in inner
    response = get_response(request)
               ^^^^^^^^^^^^^^^^^^^^^
  File "C:\Users\holmi\PycharmProjects\djangoProject\.venv\Lib\site-packages\django\core\handlers\base.py", line 197, in _get_response
    response = wrapped_callback(request, *callback_args, **callback_kwargs)
               ^^^^^^^^^^^^^^^^^^^^^^^^^^^^^^^^^^^^^^^^^^^^^^^^^^^^^^^^^^^^
  File "C:\Users\holmi\PycharmProjects\djangoProject\.venv\Lib\site-packages\django\views\decorators\csrf.py", line 65, in _view_wrapper
    return view_func(request, *args, **kwargs)
           ^^^^^^^^^^^^^^^^^^^^^^^^^^^^^^^^^^^
  File "C:\Users\holmi\PycharmProjects\djangoProject\.venv\Lib\site-packages\django\views\generic\base.py", line 104, in view
    return self.dispatch(request, *args, **kwargs)
           ^^^^^^^^^^^^^^^^^^^^^^^^^^^^^^^^^^^^^^^
  File "C:\Users\holmi\PycharmProjects\djangoProject\.venv\Lib\site-packages\rest_framework\views.py", line 509, in dispatch
    response = self.handle_exception(exc)
               ^^^^^^^^^^^^^^^^^^^^^^^^^^
  File "C:\Users\holmi\PycharmProjects\djangoProject\.venv\Lib\site-packages\rest_framework\views.py", line 469, in handle_exception
    self.raise_uncaught_exception(exc)
  File "C:\Users\holmi\PycharmProjects\djangoProject\.venv\Lib\site-packages\rest_framework\views.py", line 480, in raise_uncaught_exception
    raise exc
  File "C:\Users\holmi\PycharmProjects\djangoProject\.venv\Lib\site-packages\rest_framework\views.py", line 506, in dispatch
    response = handler(request, *args, **kwargs)
               ^^^^^^^^^^^^^^^^^^^^^^^^^^^^^^^^^
  File "C:\Users\holmi\PycharmProjects\djangoProject\.venv\Lib\site-packages\rest_framework\decorators.py", line 50, in handler
    return func(*args, **kwargs)
           ^^^^^^^^^^^^^^^^^^^^^
  File "C:\Users\holmi\PycharmProjects\djangoProject\Mamma_Mia\views.py", line 20, in create_customer
    customer = serializer.save()
               ^^^^^^^^^^^^^^^^^
  File "C:\Users\holmi\PycharmProjects\djangoProject\.venv\Lib\site-packages\rest_framework\serializers.py", line 212, in save
    self.instance = self.create(validated_data)
                    ^^^^^^^^^^^^^^^^^^^^^^^^^^^
  File "C:\Users\holmi\PycharmProjects\djangoProject\Mamma_Mia\serializer.py", line 42, in create
    customer = Customer.objects.create_user(**validated_data)
               ^^^^^^^^^^^^^^^^^^^^^^^^^^^^^^^^^^^^^^^^^^^^^^
  File "C:\Users\holmi\PycharmProjects\djangoProject\Mamma_Mia\models.py", line 17, in create_user
    user.save(using=self._db)
  File "C:\Users\holmi\PycharmProjects\djangoProject\.venv\Lib\site-packages\django\contrib\auth\base_user.py", line 78, in save
    super().save(*args, **kwargs)
  File "C:\Users\holmi\PycharmProjects\djangoProject\.venv\Lib\site-packages\django\db\models\base.py", line 822, in save
    self.save_base(
  File "C:\Users\holmi\PycharmProjects\djangoProject\.venv\Lib\site-packages\django\db\models\base.py", line 909, in save_base
    updated = self._save_table(
              ^^^^^^^^^^^^^^^^^
  File "C:\Users\holmi\PycharmProjects\djangoProject\.venv\Lib\site-packages\django\db\models\base.py", line 1067, in _save_table
    results = self._do_insert(
              ^^^^^^^^^^^^^^^^
  File "C:\Users\holmi\PycharmProjects\djangoProject\.venv\Lib\site-packages\django\db\models\base.py", line 1108, in _do_insert
    return manager._insert(
           ^^^^^^^^^^^^^^^^
  File "C:\Users\holmi\PycharmProjects\djangoProject\.venv\Lib\site-packages\django\db\models\manager.py", line 87, in manager_method
    return getattr(self.get_queryset(), name)(*args, **kwargs)
           ^^^^^^^^^^^^^^^^^^^^^^^^^^^^^^^^^^^^^^^^^^^^^^^^^^^
  File "C:\Users\holmi\PycharmProjects\djangoProject\.venv\Lib\site-packages\django\db\models\query.py", line 1847, in _insert
    return query.get_compiler(using=using).execute_sql(returning_fields)
           ^^^^^^^^^^^^^^^^^^^^^^^^^^^^^^^^^^^^^^^^^^^^^^^^^^^^^^^^^^^^^
  File "C:\Users\holmi\PycharmProjects\djangoProject\.venv\Lib\site-packages\django\db\models\sql\compiler.py", line 1823, in execute_sql
    cursor.execute(sql, params)
  File "C:\Users\holmi\PycharmProjects\djangoProject\.venv\Lib\site-packages\django\db\backends\utils.py", line 122, in execute
    return super().execute(sql, params)
           ^^^^^^^^^^^^^^^^^^^^^^^^^^^^
  File "C:\Users\holmi\PycharmProjects\djangoProject\.venv\Lib\site-packages\django\db\backends\utils.py", line 79, in execute
    return self._execute_with_wrappers(
           ^^^^^^^^^^^^^^^^^^^^^^^^^^^^
  File "C:\Users\holmi\PycharmProjects\djangoProject\.venv\Lib\site-packages\django\db\backends\utils.py", line 92, in _execute_with_wrappers
    return executor(sql, params, many, context)
           ^^^^^^^^^^^^^^^^^^^^^^^^^^^^^^^^^^^^
  File "C:\Users\holmi\PycharmProjects\djangoProject\.venv\Lib\site-packages\django\db\backends\utils.py", line 100, in _execute
    with self.db.wrap_database_errors:
  File "C:\Users\holmi\PycharmProjects\djangoProject\.venv\Lib\site-packages\django\db\utils.py", line 91, in __exit__
    raise dj_exc_value.with_traceback(traceback) from exc_value
  File "C:\Users\holmi\PycharmProjects\djangoProject\.venv\Lib\site-packages\django\db\backends\utils.py", line 105, in _execute
    return self.cursor.execute(sql, params)
           ^^^^^^^^^^^^^^^^^^^^^^^^^^^^^^^^
django.db.utils.IntegrityError: ОШИБКА:  значение NULL в столбце "age" отношения "Mamma_Mia_customer" нарушает ограничение NOT NULL
DETAIL:  Ошибочная строка содержит (2, user123, user123@example.com, pbkdf2_sha256$720000$7m0BtyVEt3svOvetINJnSM$v9ok1PHIzAK3wCWmv+97..., 2024-03-07 00:02:33.773706+00, null, t, f, null).

2024-03-07 05:02:42,204 - ERROR - Internal Server Error: /auth/sign-up/customer/
Traceback (most recent call last):
  File "C:\Users\holmi\PycharmProjects\djangoProject\.venv\Lib\site-packages\django\db\backends\utils.py", line 105, in _execute
    return self.cursor.execute(sql, params)
           ^^^^^^^^^^^^^^^^^^^^^^^^^^^^^^^^
psycopg2.errors.NotNullViolation: ОШИБКА:  значение NULL в столбце "age" отношения "Mamma_Mia_customer" нарушает ограничение NOT NULL
DETAIL:  Ошибочная строка содержит (3, user123, user123@example.com, pbkdf2_sha256$720000$e3biPw0kf4pXUpH3qMiqEX$KdDG5YFhH0wwMCZhs8CP..., 2024-03-07 00:02:42.132167+00, null, t, f, null).


The above exception was the direct cause of the following exception:

Traceback (most recent call last):
  File "C:\Users\holmi\PycharmProjects\djangoProject\.venv\Lib\site-packages\django\core\handlers\exception.py", line 55, in inner
    response = get_response(request)
               ^^^^^^^^^^^^^^^^^^^^^
  File "C:\Users\holmi\PycharmProjects\djangoProject\.venv\Lib\site-packages\django\core\handlers\base.py", line 197, in _get_response
    response = wrapped_callback(request, *callback_args, **callback_kwargs)
               ^^^^^^^^^^^^^^^^^^^^^^^^^^^^^^^^^^^^^^^^^^^^^^^^^^^^^^^^^^^^
  File "C:\Users\holmi\PycharmProjects\djangoProject\.venv\Lib\site-packages\django\views\decorators\csrf.py", line 65, in _view_wrapper
    return view_func(request, *args, **kwargs)
           ^^^^^^^^^^^^^^^^^^^^^^^^^^^^^^^^^^^
  File "C:\Users\holmi\PycharmProjects\djangoProject\.venv\Lib\site-packages\django\views\generic\base.py", line 104, in view
    return self.dispatch(request, *args, **kwargs)
           ^^^^^^^^^^^^^^^^^^^^^^^^^^^^^^^^^^^^^^^
  File "C:\Users\holmi\PycharmProjects\djangoProject\.venv\Lib\site-packages\rest_framework\views.py", line 509, in dispatch
    response = self.handle_exception(exc)
               ^^^^^^^^^^^^^^^^^^^^^^^^^^
  File "C:\Users\holmi\PycharmProjects\djangoProject\.venv\Lib\site-packages\rest_framework\views.py", line 469, in handle_exception
    self.raise_uncaught_exception(exc)
  File "C:\Users\holmi\PycharmProjects\djangoProject\.venv\Lib\site-packages\rest_framework\views.py", line 480, in raise_uncaught_exception
    raise exc
  File "C:\Users\holmi\PycharmProjects\djangoProject\.venv\Lib\site-packages\rest_framework\views.py", line 506, in dispatch
    response = handler(request, *args, **kwargs)
               ^^^^^^^^^^^^^^^^^^^^^^^^^^^^^^^^^
  File "C:\Users\holmi\PycharmProjects\djangoProject\.venv\Lib\site-packages\rest_framework\decorators.py", line 50, in handler
    return func(*args, **kwargs)
           ^^^^^^^^^^^^^^^^^^^^^
  File "C:\Users\holmi\PycharmProjects\djangoProject\Mamma_Mia\views.py", line 20, in create_customer
    customer = serializer.save()
               ^^^^^^^^^^^^^^^^^
  File "C:\Users\holmi\PycharmProjects\djangoProject\.venv\Lib\site-packages\rest_framework\serializers.py", line 212, in save
    self.instance = self.create(validated_data)
                    ^^^^^^^^^^^^^^^^^^^^^^^^^^^
  File "C:\Users\holmi\PycharmProjects\djangoProject\Mamma_Mia\serializer.py", line 42, in create
    customer = Customer.objects.create_user(**validated_data)
               ^^^^^^^^^^^^^^^^^^^^^^^^^^^^^^^^^^^^^^^^^^^^^^
  File "C:\Users\holmi\PycharmProjects\djangoProject\Mamma_Mia\models.py", line 17, in create_user
    user.save(using=self._db)
  File "C:\Users\holmi\PycharmProjects\djangoProject\.venv\Lib\site-packages\django\contrib\auth\base_user.py", line 78, in save
    super().save(*args, **kwargs)
  File "C:\Users\holmi\PycharmProjects\djangoProject\.venv\Lib\site-packages\django\db\models\base.py", line 822, in save
    self.save_base(
  File "C:\Users\holmi\PycharmProjects\djangoProject\.venv\Lib\site-packages\django\db\models\base.py", line 909, in save_base
    updated = self._save_table(
              ^^^^^^^^^^^^^^^^^
  File "C:\Users\holmi\PycharmProjects\djangoProject\.venv\Lib\site-packages\django\db\models\base.py", line 1067, in _save_table
    results = self._do_insert(
              ^^^^^^^^^^^^^^^^
  File "C:\Users\holmi\PycharmProjects\djangoProject\.venv\Lib\site-packages\django\db\models\base.py", line 1108, in _do_insert
    return manager._insert(
           ^^^^^^^^^^^^^^^^
  File "C:\Users\holmi\PycharmProjects\djangoProject\.venv\Lib\site-packages\django\db\models\manager.py", line 87, in manager_method
    return getattr(self.get_queryset(), name)(*args, **kwargs)
           ^^^^^^^^^^^^^^^^^^^^^^^^^^^^^^^^^^^^^^^^^^^^^^^^^^^
  File "C:\Users\holmi\PycharmProjects\djangoProject\.venv\Lib\site-packages\django\db\models\query.py", line 1847, in _insert
    return query.get_compiler(using=using).execute_sql(returning_fields)
           ^^^^^^^^^^^^^^^^^^^^^^^^^^^^^^^^^^^^^^^^^^^^^^^^^^^^^^^^^^^^^
  File "C:\Users\holmi\PycharmProjects\djangoProject\.venv\Lib\site-packages\django\db\models\sql\compiler.py", line 1823, in execute_sql
    cursor.execute(sql, params)
  File "C:\Users\holmi\PycharmProjects\djangoProject\.venv\Lib\site-packages\django\db\backends\utils.py", line 122, in execute
    return super().execute(sql, params)
           ^^^^^^^^^^^^^^^^^^^^^^^^^^^^
  File "C:\Users\holmi\PycharmProjects\djangoProject\.venv\Lib\site-packages\django\db\backends\utils.py", line 79, in execute
    return self._execute_with_wrappers(
           ^^^^^^^^^^^^^^^^^^^^^^^^^^^^
  File "C:\Users\holmi\PycharmProjects\djangoProject\.venv\Lib\site-packages\django\db\backends\utils.py", line 92, in _execute_with_wrappers
    return executor(sql, params, many, context)
           ^^^^^^^^^^^^^^^^^^^^^^^^^^^^^^^^^^^^
  File "C:\Users\holmi\PycharmProjects\djangoProject\.venv\Lib\site-packages\django\db\backends\utils.py", line 100, in _execute
    with self.db.wrap_database_errors:
  File "C:\Users\holmi\PycharmProjects\djangoProject\.venv\Lib\site-packages\django\db\utils.py", line 91, in __exit__
    raise dj_exc_value.with_traceback(traceback) from exc_value
  File "C:\Users\holmi\PycharmProjects\djangoProject\.venv\Lib\site-packages\django\db\backends\utils.py", line 105, in _execute
    return self.cursor.execute(sql, params)
           ^^^^^^^^^^^^^^^^^^^^^^^^^^^^^^^^
django.db.utils.IntegrityError: ОШИБКА:  значение NULL в столбце "age" отношения "Mamma_Mia_customer" нарушает ограничение NOT NULL
DETAIL:  Ошибочная строка содержит (3, user123, user123@example.com, pbkdf2_sha256$720000$e3biPw0kf4pXUpH3qMiqEX$KdDG5YFhH0wwMCZhs8CP..., 2024-03-07 00:02:42.132167+00, null, t, f, null).

2024-03-07 05:05:12,553 - INFO - C:\Users\holmi\PycharmProjects\djangoProject\Mamma_Mia\models.py changed, reloading.
2024-03-07 05:05:13,247 - INFO - Watching for file changes with StatReloader
2024-03-07 05:05:26,518 - INFO - Watching for file changes with StatReloader
2024-03-07 05:05:35,629 - ERROR - Internal Server Error: /auth/sign-up/customer/
Traceback (most recent call last):
  File "C:\Users\holmi\PycharmProjects\djangoProject\.venv\Lib\site-packages\django\core\handlers\exception.py", line 55, in inner
    response = get_response(request)
               ^^^^^^^^^^^^^^^^^^^^^
  File "C:\Users\holmi\PycharmProjects\djangoProject\.venv\Lib\site-packages\django\core\handlers\base.py", line 197, in _get_response
    response = wrapped_callback(request, *callback_args, **callback_kwargs)
               ^^^^^^^^^^^^^^^^^^^^^^^^^^^^^^^^^^^^^^^^^^^^^^^^^^^^^^^^^^^^
  File "C:\Users\holmi\PycharmProjects\djangoProject\.venv\Lib\site-packages\django\views\decorators\csrf.py", line 65, in _view_wrapper
    return view_func(request, *args, **kwargs)
           ^^^^^^^^^^^^^^^^^^^^^^^^^^^^^^^^^^^
  File "C:\Users\holmi\PycharmProjects\djangoProject\.venv\Lib\site-packages\django\views\generic\base.py", line 104, in view
    return self.dispatch(request, *args, **kwargs)
           ^^^^^^^^^^^^^^^^^^^^^^^^^^^^^^^^^^^^^^^
  File "C:\Users\holmi\PycharmProjects\djangoProject\.venv\Lib\site-packages\rest_framework\views.py", line 509, in dispatch
    response = self.handle_exception(exc)
               ^^^^^^^^^^^^^^^^^^^^^^^^^^
  File "C:\Users\holmi\PycharmProjects\djangoProject\.venv\Lib\site-packages\rest_framework\views.py", line 469, in handle_exception
    self.raise_uncaught_exception(exc)
  File "C:\Users\holmi\PycharmProjects\djangoProject\.venv\Lib\site-packages\rest_framework\views.py", line 480, in raise_uncaught_exception
    raise exc
  File "C:\Users\holmi\PycharmProjects\djangoProject\.venv\Lib\site-packages\rest_framework\views.py", line 506, in dispatch
    response = handler(request, *args, **kwargs)
               ^^^^^^^^^^^^^^^^^^^^^^^^^^^^^^^^^
  File "C:\Users\holmi\PycharmProjects\djangoProject\.venv\Lib\site-packages\rest_framework\decorators.py", line 50, in handler
    return func(*args, **kwargs)
           ^^^^^^^^^^^^^^^^^^^^^
  File "C:\Users\holmi\PycharmProjects\djangoProject\Mamma_Mia\views.py", line 21, in create_customer
    Customer.objects.update_last_login(customer)  # Обновляем дату последнего входа
    ^^^^^^^^^^^^^^^^^^^^^^^^^^^^^^^^^^^^^^^^^^^^
  File "C:\Users\holmi\PycharmProjects\djangoProject\Mamma_Mia\models.py", line 33, in update_last_login
    user.last_login = timezone.now()
                      ^^^^^^^^^^^^
AttributeError: type object 'datetime.timezone' has no attribute 'now'
2024-03-07 05:07:58,515 - INFO - Watching for file changes with StatReloader
2024-03-07 05:08:01,546 - WARNING - Bad Request: /auth/sign-up/customer/
2024-03-07 05:10:48,243 - INFO - Watching for file changes with StatReloader
2024-03-07 05:10:52,033 - ERROR - Ошибка валидации данных: {'username': [ErrorDetail(string='customer with this username already exists.', code='unique')], 'email': [ErrorDetail(string='customer with this email already exists.', code='unique')]}
2024-03-07 05:10:52,034 - WARNING - Bad Request: /auth/sign-up/customer/
2024-03-07 05:11:12,233 - INFO - Watching for file changes with StatReloader
2024-03-07 05:11:19,632 - ERROR - Ошибка валидации данных: {'username': [ErrorDetail(string='customer with this username already exists.', code='unique')], 'email': [ErrorDetail(string='customer with this email already exists.', code='unique')]}
2024-03-07 05:11:19,633 - WARNING - Bad Request: /auth/sign-up/customer/
2024-03-07 05:11:50,561 - ERROR - Ошибка валидации данных: {'email': [ErrorDetail(string='Enter a valid email address.', code='invalid')]}
2024-03-07 05:11:50,561 - WARNING - Bad Request: /auth/sign-up/customer/
2024-03-07 05:13:24,431 - ERROR - Internal Server Error: /auth/sign-up/customer/
Traceback (most recent call last):
  File "C:\Users\holmi\PycharmProjects\djangoProject\.venv\Lib\site-packages\django\core\handlers\exception.py", line 55, in inner
    response = get_response(request)
               ^^^^^^^^^^^^^^^^^^^^^
  File "C:\Users\holmi\PycharmProjects\djangoProject\.venv\Lib\site-packages\django\core\handlers\base.py", line 197, in _get_response
    response = wrapped_callback(request, *callback_args, **callback_kwargs)
               ^^^^^^^^^^^^^^^^^^^^^^^^^^^^^^^^^^^^^^^^^^^^^^^^^^^^^^^^^^^^
  File "C:\Users\holmi\PycharmProjects\djangoProject\.venv\Lib\site-packages\django\views\decorators\csrf.py", line 65, in _view_wrapper
    return view_func(request, *args, **kwargs)
           ^^^^^^^^^^^^^^^^^^^^^^^^^^^^^^^^^^^
  File "C:\Users\holmi\PycharmProjects\djangoProject\.venv\Lib\site-packages\django\views\generic\base.py", line 104, in view
    return self.dispatch(request, *args, **kwargs)
           ^^^^^^^^^^^^^^^^^^^^^^^^^^^^^^^^^^^^^^^
  File "C:\Users\holmi\PycharmProjects\djangoProject\.venv\Lib\site-packages\rest_framework\views.py", line 509, in dispatch
    response = self.handle_exception(exc)
               ^^^^^^^^^^^^^^^^^^^^^^^^^^
  File "C:\Users\holmi\PycharmProjects\djangoProject\.venv\Lib\site-packages\rest_framework\views.py", line 469, in handle_exception
    self.raise_uncaught_exception(exc)
  File "C:\Users\holmi\PycharmProjects\djangoProject\.venv\Lib\site-packages\rest_framework\views.py", line 480, in raise_uncaught_exception
    raise exc
  File "C:\Users\holmi\PycharmProjects\djangoProject\.venv\Lib\site-packages\rest_framework\views.py", line 506, in dispatch
    response = handler(request, *args, **kwargs)
               ^^^^^^^^^^^^^^^^^^^^^^^^^^^^^^^^^
  File "C:\Users\holmi\PycharmProjects\djangoProject\.venv\Lib\site-packages\rest_framework\decorators.py", line 50, in handler
    return func(*args, **kwargs)
           ^^^^^^^^^^^^^^^^^^^^^
  File "C:\Users\holmi\PycharmProjects\djangoProject\Mamma_Mia\views.py", line 35, in create_customer
    Customer.objects.update_last_login(customer)  # Обновляем дату последнего входа
    ^^^^^^^^^^^^^^^^^^^^^^^^^^^^^^^^^^^^^^^^^^^^
  File "C:\Users\holmi\PycharmProjects\djangoProject\Mamma_Mia\models.py", line 33, in update_last_login
    user.last_login = timezone.now()  # Замените timezone.now на timezone.now()
                      ^^^^^^^^^^^^
AttributeError: type object 'datetime.timezone' has no attribute 'now'
2024-03-07 05:16:15,127 - ERROR - Ошибка валидации данных: {'username': [ErrorDetail(string='This field is required.', code='required')], 'email': [ErrorDetail(string='Enter a valid email address.', code='invalid')]}
2024-03-07 05:16:15,127 - WARNING - Bad Request: /auth/sign-up/customer/
2024-03-07 05:17:16,477 - ERROR - Ошибка валидации данных: {'username': [ErrorDetail(string='This field is required.', code='required')], 'email': [ErrorDetail(string='Enter a valid email address.', code='invalid')]}
2024-03-07 05:17:16,477 - WARNING - Bad Request: /auth/sign-up/customer/
2024-03-07 05:19:00,092 - ERROR - Internal Server Error: /auth/sign-up/customer/
Traceback (most recent call last):
  File "C:\Users\holmi\PycharmProjects\djangoProject\.venv\Lib\site-packages\django\core\handlers\exception.py", line 55, in inner
    response = get_response(request)
               ^^^^^^^^^^^^^^^^^^^^^
  File "C:\Users\holmi\PycharmProjects\djangoProject\.venv\Lib\site-packages\django\core\handlers\base.py", line 197, in _get_response
    response = wrapped_callback(request, *callback_args, **callback_kwargs)
               ^^^^^^^^^^^^^^^^^^^^^^^^^^^^^^^^^^^^^^^^^^^^^^^^^^^^^^^^^^^^
  File "C:\Users\holmi\PycharmProjects\djangoProject\.venv\Lib\site-packages\django\views\decorators\csrf.py", line 65, in _view_wrapper
    return view_func(request, *args, **kwargs)
           ^^^^^^^^^^^^^^^^^^^^^^^^^^^^^^^^^^^
  File "C:\Users\holmi\PycharmProjects\djangoProject\.venv\Lib\site-packages\django\views\generic\base.py", line 104, in view
    return self.dispatch(request, *args, **kwargs)
           ^^^^^^^^^^^^^^^^^^^^^^^^^^^^^^^^^^^^^^^
  File "C:\Users\holmi\PycharmProjects\djangoProject\.venv\Lib\site-packages\rest_framework\views.py", line 509, in dispatch
    response = self.handle_exception(exc)
               ^^^^^^^^^^^^^^^^^^^^^^^^^^
  File "C:\Users\holmi\PycharmProjects\djangoProject\.venv\Lib\site-packages\rest_framework\views.py", line 469, in handle_exception
    self.raise_uncaught_exception(exc)
  File "C:\Users\holmi\PycharmProjects\djangoProject\.venv\Lib\site-packages\rest_framework\views.py", line 480, in raise_uncaught_exception
    raise exc
  File "C:\Users\holmi\PycharmProjects\djangoProject\.venv\Lib\site-packages\rest_framework\views.py", line 506, in dispatch
    response = handler(request, *args, **kwargs)
               ^^^^^^^^^^^^^^^^^^^^^^^^^^^^^^^^^
  File "C:\Users\holmi\PycharmProjects\djangoProject\.venv\Lib\site-packages\rest_framework\decorators.py", line 50, in handler
    return func(*args, **kwargs)
           ^^^^^^^^^^^^^^^^^^^^^
  File "C:\Users\holmi\PycharmProjects\djangoProject\Mamma_Mia\views.py", line 35, in create_customer
    Customer.objects.update_last_login(customer)  # Обновляем дату последнего входа
    ^^^^^^^^^^^^^^^^^^^^^^^^^^^^^^^^^^^^^^^^^^^^
  File "C:\Users\holmi\PycharmProjects\djangoProject\Mamma_Mia\models.py", line 33, in update_last_login
    user.last_login = timezone.now()  # Замените timezone.now на timezone.now()
                      ^^^^^^^^^^^^
AttributeError: type object 'datetime.timezone' has no attribute 'now'
2024-03-07 05:20:33,174 - ERROR - Ошибка валидации данных: {'username': [ErrorDetail(string='customer with this username already exists.', code='unique')], 'email': [ErrorDetail(string='customer with this email already exists.', code='unique')]}
2024-03-07 05:20:33,174 - WARNING - Bad Request: /auth/sign-up/customer/
2024-03-07 05:22:34,944 - INFO - Watching for file changes with StatReloader
2024-03-07 05:22:39,978 - WARNING - Bad Request: /auth/sign-up/customer/
2024-03-07 05:23:40,649 - WARNING - Bad Request: /auth/sign-up/customer/
2024-03-07 05:26:06,915 - INFO - Watching for file changes with StatReloader
2024-03-07 05:26:10,771 - WARNING - Bad Request: /auth/sign-up/customer/
2024-03-07 05:26:34,184 - WARNING - Bad Request: /auth/sign-up/customer/
2024-03-07 05:28:00,081 - INFO - Watching for file changes with StatReloader
2024-03-07 05:28:14,984 - ERROR - Ошибка при регистрации пользователя: customer with this email already exists.
2024-03-07 05:28:14,985 - WARNING - Bad Request: /auth/sign-up/customer/
2024-03-07 05:30:07,831 - WARNING - Method Not Allowed: /auth/sign-in/customer/
2024-03-07 05:30:13,598 - WARNING - Bad Request: /auth/sign-in/customer/
2024-03-07 05:36:23,293 - INFO - Watching for file changes with StatReloader
2024-03-07 05:36:33,424 - INFO - Watching for file changes with StatReloader
2024-03-07 05:46:29,837 - INFO - Watching for file changes with StatReloader
2024-03-07 05:54:26,950 - INFO - C:\Users\holmi\PycharmProjects\djangoProject\Mamma_Mia\views.py changed, reloading.
2024-03-07 05:54:27,765 - INFO - Watching for file changes with StatReloader
2024-03-07 05:55:18,039 - INFO - Watching for file changes with StatReloader
2024-03-07 05:57:08,064 - INFO - Watching for file changes with StatReloader
2024-03-07 06:03:15,794 - WARNING - Bad Request: /auth/sign-up/customer/
2024-03-07 06:08:47,655 - INFO - Watching for file changes with StatReloader
2024-03-07 06:17:56,437 - WARNING - Not Found: /customers/auth/sign-in/customer/
2024-03-07 06:18:40,221 - WARNING - Bad Request: /auth/sign-in/customer/
2024-03-07 06:19:14,447 - WARNING - Method Not Allowed: /customers/
2024-03-07 06:21:25,552 - WARNING - Unauthorized: /auth/sign-in/customer/
2024-03-07 06:27:50,002 - ERROR - Ошибка при регистрации пользователя: customer with this username already exists.
2024-03-07 06:27:50,003 - ERROR - Ошибка при регистрации пользователя: This field is required.
2024-03-07 06:27:50,004 - WARNING - Bad Request: /auth/sign-up/customer/
2024-03-07 06:28:09,350 - ERROR - Ошибка при регистрации пользователя: This field is required.
2024-03-07 06:28:09,351 - WARNING - Bad Request: /auth/sign-up/customer/
2024-03-07 08:53:37,801 - INFO - Watching for file changes with StatReloader
2024-03-07 08:53:45,798 - ERROR - Ошибка при регистрации пользователя: This field is required.
2024-03-07 08:53:45,799 - WARNING - Bad Request: /auth/sign-up/customer/
2024-03-07 08:55:20,095 - WARNING - Unauthorized: /auth/sign-in/customer/
2024-03-07 08:57:26,660 - WARNING - Unauthorized: /auth/sign-in/customer/
2024-03-07 08:57:46,274 - ERROR - Ошибка при регистрации пользователя: customer with this username already exists.
2024-03-07 08:57:46,274 - ERROR - Ошибка при регистрации пользователя: customer with this email already exists.
2024-03-07 08:57:46,274 - WARNING - Bad Request: /auth/sign-up/customer/
2024-03-07 09:03:30,730 - INFO - C:\Users\holmi\PycharmProjects\djangoProject\Mamma_Mia\views.py changed, reloading.
2024-03-07 09:03:31,785 - INFO - Watching for file changes with StatReloader
2024-03-07 09:09:33,554 - INFO - C:\Users\holmi\PycharmProjects\djangoProject\Mamma_Mia\views.py changed, reloading.
2024-03-07 09:09:34,357 - INFO - Watching for file changes with StatReloader
2024-03-07 09:09:52,489 - INFO - Watching for file changes with StatReloader
2024-03-07 09:12:57,786 - INFO - Watching for file changes with StatReloader
2024-03-07 09:13:05,746 - ERROR - Ошибка при регистрации пользователя: CustomerManager.create_user() missing 1 required positional argument: 'email'
2024-03-07 09:13:05,746 - ERROR - Internal Server Error: /auth/sign-up/customer/
2024-03-07 09:13:11,786 - ERROR - Ошибка при регистрации пользователя: CustomerManager.create_user() missing 1 required positional argument: 'email'
2024-03-07 09:13:11,786 - ERROR - Internal Server Error: /auth/sign-up/customer/
2024-03-07 09:15:52,249 - INFO - Watching for file changes with StatReloader
2024-03-07 09:15:58,255 - ERROR - Ошибка при регистрации пользователя: CustomerManager.create_user() missing 1 required positional argument: 'email'
2024-03-07 09:15:58,257 - ERROR - Internal Server Error: /auth/sign-up/customer/
2024-03-07 09:17:39,771 - INFO - Watching for file changes with StatReloader
2024-03-07 09:18:41,627 - WARNING - Unauthorized: /auth/sign-in/customer/
2024-03-07 09:19:42,277 - WARNING - Method Not Allowed: /auth/sign-in/customer/
2024-03-07 09:20:14,310 - WARNING - Unauthorized: /auth/sign-in/customer/
2024-03-07 09:23:52,934 - ERROR - Ошибка при регистрации пользователя: CustomerManager.create_user() missing 1 required positional argument: 'email'
2024-03-07 09:23:52,934 - ERROR - Internal Server Error: /auth/sign-up/customer/
2024-03-07 09:24:02,749 - ERROR - Ошибка при регистрации пользователя: CustomerManager.create_user() missing 1 required positional argument: 'email'
2024-03-07 09:24:02,749 - ERROR - Internal Server Error: /auth/sign-up/customer/
2024-03-07 09:24:17,468 - INFO - Watching for file changes with StatReloader
2024-03-07 09:24:51,616 - INFO - Watching for file changes with StatReloader
2024-03-07 09:25:22,595 - INFO - Watching for file changes with StatReloader
2024-03-07 09:35:16,539 - INFO - Watching for file changes with StatReloader
2024-03-07 10:08:52,751 - INFO - Watching for file changes with StatReloader
2024-03-07 10:08:56,277 - INFO - Watching for file changes with StatReloader
2024-03-07 10:09:34,713 - ERROR - Internal Server Error: /ingredients/6/
Traceback (most recent call last):
  File "C:\Users\holmi\PycharmProjects\djangoProject\.venv\Lib\site-packages\django\core\handlers\exception.py", line 55, in inner
    response = get_response(request)
               ^^^^^^^^^^^^^^^^^^^^^
  File "C:\Users\holmi\PycharmProjects\djangoProject\.venv\Lib\site-packages\django\core\handlers\base.py", line 197, in _get_response
    response = wrapped_callback(request, *callback_args, **callback_kwargs)
               ^^^^^^^^^^^^^^^^^^^^^^^^^^^^^^^^^^^^^^^^^^^^^^^^^^^^^^^^^^^^
  File "C:\Users\holmi\PycharmProjects\djangoProject\.venv\Lib\site-packages\django\views\decorators\csrf.py", line 65, in _view_wrapper
    return view_func(request, *args, **kwargs)
           ^^^^^^^^^^^^^^^^^^^^^^^^^^^^^^^^^^^
  File "C:\Users\holmi\PycharmProjects\djangoProject\.venv\Lib\site-packages\rest_framework\viewsets.py", line 125, in view
    return self.dispatch(request, *args, **kwargs)
           ^^^^^^^^^^^^^^^^^^^^^^^^^^^^^^^^^^^^^^^
  File "C:\Users\holmi\PycharmProjects\djangoProject\.venv\Lib\site-packages\rest_framework\views.py", line 509, in dispatch
    response = self.handle_exception(exc)
               ^^^^^^^^^^^^^^^^^^^^^^^^^^
  File "C:\Users\holmi\PycharmProjects\djangoProject\.venv\Lib\site-packages\rest_framework\views.py", line 469, in handle_exception
    self.raise_uncaught_exception(exc)
  File "C:\Users\holmi\PycharmProjects\djangoProject\.venv\Lib\site-packages\rest_framework\views.py", line 480, in raise_uncaught_exception
    raise exc
  File "C:\Users\holmi\PycharmProjects\djangoProject\.venv\Lib\site-packages\rest_framework\views.py", line 506, in dispatch
    response = handler(request, *args, **kwargs)
               ^^^^^^^^^^^^^^^^^^^^^^^^^^^^^^^^^
  File "C:\Users\holmi\PycharmProjects\djangoProject\.venv\Lib\site-packages\rest_framework\mixins.py", line 56, in retrieve
    return Response(serializer.data)
                    ^^^^^^^^^^^^^^^
  File "C:\Users\holmi\PycharmProjects\djangoProject\.venv\Lib\site-packages\rest_framework\serializers.py", line 555, in data
    ret = super().data
          ^^^^^^^^^^^^
  File "C:\Users\holmi\PycharmProjects\djangoProject\.venv\Lib\site-packages\rest_framework\serializers.py", line 253, in data
    self._data = self.to_representation(self.instance)
                 ^^^^^^^^^^^^^^^^^^^^^^^^^^^^^^^^^^^^^
  File "C:\Users\holmi\PycharmProjects\djangoProject\.venv\Lib\site-packages\rest_framework\serializers.py", line 507, in to_representation
    for field in fields:
  File "C:\Users\holmi\PycharmProjects\djangoProject\.venv\Lib\site-packages\rest_framework\serializers.py", line 368, in _readable_fields
    for field in self.fields.values():
                 ^^^^^^^^^^^
  File "C:\Users\holmi\PycharmProjects\djangoProject\.venv\Lib\site-packages\django\utils\functional.py", line 47, in __get__
    res = instance.__dict__[self.name] = self.func(instance)
                                         ^^^^^^^^^^^^^^^^^^^
  File "C:\Users\holmi\PycharmProjects\djangoProject\.venv\Lib\site-packages\rest_framework\serializers.py", line 356, in fields
    for key, value in self.get_fields().items():
                      ^^^^^^^^^^^^^^^^^
  File "C:\Users\holmi\PycharmProjects\djangoProject\.venv\Lib\site-packages\rest_framework\serializers.py", line 1052, in get_fields
    field_names = self.get_field_names(declared_fields, info)
                  ^^^^^^^^^^^^^^^^^^^^^^^^^^^^^^^^^^^^^^^^^^^
  File "C:\Users\holmi\PycharmProjects\djangoProject\.venv\Lib\site-packages\rest_framework\serializers.py", line 1106, in get_field_names
    raise TypeError(
TypeError: The `fields` option must be a list or tuple or "__all__". Got str.
2024-03-07 10:09:39,940 - ERROR - Internal Server Error: /ingredients/4/
Traceback (most recent call last):
  File "C:\Users\holmi\PycharmProjects\djangoProject\.venv\Lib\site-packages\django\core\handlers\exception.py", line 55, in inner
    response = get_response(request)
               ^^^^^^^^^^^^^^^^^^^^^
  File "C:\Users\holmi\PycharmProjects\djangoProject\.venv\Lib\site-packages\django\core\handlers\base.py", line 197, in _get_response
    response = wrapped_callback(request, *callback_args, **callback_kwargs)
               ^^^^^^^^^^^^^^^^^^^^^^^^^^^^^^^^^^^^^^^^^^^^^^^^^^^^^^^^^^^^
  File "C:\Users\holmi\PycharmProjects\djangoProject\.venv\Lib\site-packages\django\views\decorators\csrf.py", line 65, in _view_wrapper
    return view_func(request, *args, **kwargs)
           ^^^^^^^^^^^^^^^^^^^^^^^^^^^^^^^^^^^
  File "C:\Users\holmi\PycharmProjects\djangoProject\.venv\Lib\site-packages\rest_framework\viewsets.py", line 125, in view
    return self.dispatch(request, *args, **kwargs)
           ^^^^^^^^^^^^^^^^^^^^^^^^^^^^^^^^^^^^^^^
  File "C:\Users\holmi\PycharmProjects\djangoProject\.venv\Lib\site-packages\rest_framework\views.py", line 509, in dispatch
    response = self.handle_exception(exc)
               ^^^^^^^^^^^^^^^^^^^^^^^^^^
  File "C:\Users\holmi\PycharmProjects\djangoProject\.venv\Lib\site-packages\rest_framework\views.py", line 469, in handle_exception
    self.raise_uncaught_exception(exc)
  File "C:\Users\holmi\PycharmProjects\djangoProject\.venv\Lib\site-packages\rest_framework\views.py", line 480, in raise_uncaught_exception
    raise exc
  File "C:\Users\holmi\PycharmProjects\djangoProject\.venv\Lib\site-packages\rest_framework\views.py", line 506, in dispatch
    response = handler(request, *args, **kwargs)
               ^^^^^^^^^^^^^^^^^^^^^^^^^^^^^^^^^
  File "C:\Users\holmi\PycharmProjects\djangoProject\.venv\Lib\site-packages\rest_framework\mixins.py", line 56, in retrieve
    return Response(serializer.data)
                    ^^^^^^^^^^^^^^^
  File "C:\Users\holmi\PycharmProjects\djangoProject\.venv\Lib\site-packages\rest_framework\serializers.py", line 555, in data
    ret = super().data
          ^^^^^^^^^^^^
  File "C:\Users\holmi\PycharmProjects\djangoProject\.venv\Lib\site-packages\rest_framework\serializers.py", line 253, in data
    self._data = self.to_representation(self.instance)
                 ^^^^^^^^^^^^^^^^^^^^^^^^^^^^^^^^^^^^^
  File "C:\Users\holmi\PycharmProjects\djangoProject\.venv\Lib\site-packages\rest_framework\serializers.py", line 507, in to_representation
    for field in fields:
  File "C:\Users\holmi\PycharmProjects\djangoProject\.venv\Lib\site-packages\rest_framework\serializers.py", line 368, in _readable_fields
    for field in self.fields.values():
                 ^^^^^^^^^^^
  File "C:\Users\holmi\PycharmProjects\djangoProject\.venv\Lib\site-packages\django\utils\functional.py", line 47, in __get__
    res = instance.__dict__[self.name] = self.func(instance)
                                         ^^^^^^^^^^^^^^^^^^^
  File "C:\Users\holmi\PycharmProjects\djangoProject\.venv\Lib\site-packages\rest_framework\serializers.py", line 356, in fields
    for key, value in self.get_fields().items():
                      ^^^^^^^^^^^^^^^^^
  File "C:\Users\holmi\PycharmProjects\djangoProject\.venv\Lib\site-packages\rest_framework\serializers.py", line 1052, in get_fields
    field_names = self.get_field_names(declared_fields, info)
                  ^^^^^^^^^^^^^^^^^^^^^^^^^^^^^^^^^^^^^^^^^^^
  File "C:\Users\holmi\PycharmProjects\djangoProject\.venv\Lib\site-packages\rest_framework\serializers.py", line 1106, in get_field_names
    raise TypeError(
TypeError: The `fields` option must be a list or tuple or "__all__". Got str.
2024-03-07 10:09:55,240 - ERROR - Internal Server Error: /ingredients/20/
Traceback (most recent call last):
  File "C:\Users\holmi\PycharmProjects\djangoProject\.venv\Lib\site-packages\django\core\handlers\exception.py", line 55, in inner
    response = get_response(request)
               ^^^^^^^^^^^^^^^^^^^^^
  File "C:\Users\holmi\PycharmProjects\djangoProject\.venv\Lib\site-packages\django\core\handlers\base.py", line 197, in _get_response
    response = wrapped_callback(request, *callback_args, **callback_kwargs)
               ^^^^^^^^^^^^^^^^^^^^^^^^^^^^^^^^^^^^^^^^^^^^^^^^^^^^^^^^^^^^
  File "C:\Users\holmi\PycharmProjects\djangoProject\.venv\Lib\site-packages\django\views\decorators\csrf.py", line 65, in _view_wrapper
    return view_func(request, *args, **kwargs)
           ^^^^^^^^^^^^^^^^^^^^^^^^^^^^^^^^^^^
  File "C:\Users\holmi\PycharmProjects\djangoProject\.venv\Lib\site-packages\rest_framework\viewsets.py", line 125, in view
    return self.dispatch(request, *args, **kwargs)
           ^^^^^^^^^^^^^^^^^^^^^^^^^^^^^^^^^^^^^^^
  File "C:\Users\holmi\PycharmProjects\djangoProject\.venv\Lib\site-packages\rest_framework\views.py", line 509, in dispatch
    response = self.handle_exception(exc)
               ^^^^^^^^^^^^^^^^^^^^^^^^^^
  File "C:\Users\holmi\PycharmProjects\djangoProject\.venv\Lib\site-packages\rest_framework\views.py", line 469, in handle_exception
    self.raise_uncaught_exception(exc)
  File "C:\Users\holmi\PycharmProjects\djangoProject\.venv\Lib\site-packages\rest_framework\views.py", line 480, in raise_uncaught_exception
    raise exc
  File "C:\Users\holmi\PycharmProjects\djangoProject\.venv\Lib\site-packages\rest_framework\views.py", line 506, in dispatch
    response = handler(request, *args, **kwargs)
               ^^^^^^^^^^^^^^^^^^^^^^^^^^^^^^^^^
  File "C:\Users\holmi\PycharmProjects\djangoProject\.venv\Lib\site-packages\rest_framework\mixins.py", line 56, in retrieve
    return Response(serializer.data)
                    ^^^^^^^^^^^^^^^
  File "C:\Users\holmi\PycharmProjects\djangoProject\.venv\Lib\site-packages\rest_framework\serializers.py", line 555, in data
    ret = super().data
          ^^^^^^^^^^^^
  File "C:\Users\holmi\PycharmProjects\djangoProject\.venv\Lib\site-packages\rest_framework\serializers.py", line 253, in data
    self._data = self.to_representation(self.instance)
                 ^^^^^^^^^^^^^^^^^^^^^^^^^^^^^^^^^^^^^
  File "C:\Users\holmi\PycharmProjects\djangoProject\.venv\Lib\site-packages\rest_framework\serializers.py", line 507, in to_representation
    for field in fields:
  File "C:\Users\holmi\PycharmProjects\djangoProject\.venv\Lib\site-packages\rest_framework\serializers.py", line 368, in _readable_fields
    for field in self.fields.values():
                 ^^^^^^^^^^^
  File "C:\Users\holmi\PycharmProjects\djangoProject\.venv\Lib\site-packages\django\utils\functional.py", line 47, in __get__
    res = instance.__dict__[self.name] = self.func(instance)
                                         ^^^^^^^^^^^^^^^^^^^
  File "C:\Users\holmi\PycharmProjects\djangoProject\.venv\Lib\site-packages\rest_framework\serializers.py", line 356, in fields
    for key, value in self.get_fields().items():
                      ^^^^^^^^^^^^^^^^^
  File "C:\Users\holmi\PycharmProjects\djangoProject\.venv\Lib\site-packages\rest_framework\serializers.py", line 1052, in get_fields
    field_names = self.get_field_names(declared_fields, info)
                  ^^^^^^^^^^^^^^^^^^^^^^^^^^^^^^^^^^^^^^^^^^^
  File "C:\Users\holmi\PycharmProjects\djangoProject\.venv\Lib\site-packages\rest_framework\serializers.py", line 1106, in get_field_names
    raise TypeError(
TypeError: The `fields` option must be a list or tuple or "__all__". Got str.
2024-03-07 10:10:03,825 - ERROR - Internal Server Error: /ingredients/
Traceback (most recent call last):
  File "C:\Users\holmi\PycharmProjects\djangoProject\.venv\Lib\site-packages\django\core\handlers\exception.py", line 55, in inner
    response = get_response(request)
               ^^^^^^^^^^^^^^^^^^^^^
  File "C:\Users\holmi\PycharmProjects\djangoProject\.venv\Lib\site-packages\django\core\handlers\base.py", line 197, in _get_response
    response = wrapped_callback(request, *callback_args, **callback_kwargs)
               ^^^^^^^^^^^^^^^^^^^^^^^^^^^^^^^^^^^^^^^^^^^^^^^^^^^^^^^^^^^^
  File "C:\Users\holmi\PycharmProjects\djangoProject\.venv\Lib\site-packages\django\views\decorators\csrf.py", line 65, in _view_wrapper
    return view_func(request, *args, **kwargs)
           ^^^^^^^^^^^^^^^^^^^^^^^^^^^^^^^^^^^
  File "C:\Users\holmi\PycharmProjects\djangoProject\.venv\Lib\site-packages\rest_framework\viewsets.py", line 125, in view
    return self.dispatch(request, *args, **kwargs)
           ^^^^^^^^^^^^^^^^^^^^^^^^^^^^^^^^^^^^^^^
  File "C:\Users\holmi\PycharmProjects\djangoProject\.venv\Lib\site-packages\rest_framework\views.py", line 509, in dispatch
    response = self.handle_exception(exc)
               ^^^^^^^^^^^^^^^^^^^^^^^^^^
  File "C:\Users\holmi\PycharmProjects\djangoProject\.venv\Lib\site-packages\rest_framework\views.py", line 469, in handle_exception
    self.raise_uncaught_exception(exc)
  File "C:\Users\holmi\PycharmProjects\djangoProject\.venv\Lib\site-packages\rest_framework\views.py", line 480, in raise_uncaught_exception
    raise exc
  File "C:\Users\holmi\PycharmProjects\djangoProject\.venv\Lib\site-packages\rest_framework\views.py", line 506, in dispatch
    response = handler(request, *args, **kwargs)
               ^^^^^^^^^^^^^^^^^^^^^^^^^^^^^^^^^
  File "C:\Users\holmi\PycharmProjects\djangoProject\.venv\Lib\site-packages\rest_framework\mixins.py", line 46, in list
    return Response(serializer.data)
                    ^^^^^^^^^^^^^^^
  File "C:\Users\holmi\PycharmProjects\djangoProject\.venv\Lib\site-packages\rest_framework\serializers.py", line 768, in data
    ret = super().data
          ^^^^^^^^^^^^
  File "C:\Users\holmi\PycharmProjects\djangoProject\.venv\Lib\site-packages\rest_framework\serializers.py", line 253, in data
    self._data = self.to_representation(self.instance)
                 ^^^^^^^^^^^^^^^^^^^^^^^^^^^^^^^^^^^^^
  File "C:\Users\holmi\PycharmProjects\djangoProject\.venv\Lib\site-packages\rest_framework\serializers.py", line 687, in to_representation
    self.child.to_representation(item) for item in iterable
    ^^^^^^^^^^^^^^^^^^^^^^^^^^^^^^^^^^
  File "C:\Users\holmi\PycharmProjects\djangoProject\.venv\Lib\site-packages\rest_framework\serializers.py", line 507, in to_representation
    for field in fields:
  File "C:\Users\holmi\PycharmProjects\djangoProject\.venv\Lib\site-packages\rest_framework\serializers.py", line 368, in _readable_fields
    for field in self.fields.values():
                 ^^^^^^^^^^^
  File "C:\Users\holmi\PycharmProjects\djangoProject\.venv\Lib\site-packages\django\utils\functional.py", line 47, in __get__
    res = instance.__dict__[self.name] = self.func(instance)
                                         ^^^^^^^^^^^^^^^^^^^
  File "C:\Users\holmi\PycharmProjects\djangoProject\.venv\Lib\site-packages\rest_framework\serializers.py", line 356, in fields
    for key, value in self.get_fields().items():
                      ^^^^^^^^^^^^^^^^^
  File "C:\Users\holmi\PycharmProjects\djangoProject\.venv\Lib\site-packages\rest_framework\serializers.py", line 1052, in get_fields
    field_names = self.get_field_names(declared_fields, info)
                  ^^^^^^^^^^^^^^^^^^^^^^^^^^^^^^^^^^^^^^^^^^^
  File "C:\Users\holmi\PycharmProjects\djangoProject\.venv\Lib\site-packages\rest_framework\serializers.py", line 1106, in get_field_names
    raise TypeError(
TypeError: The `fields` option must be a list or tuple or "__all__". Got str.
2024-03-07 10:11:15,411 - INFO - Watching for file changes with StatReloader
2024-03-07 10:11:30,831 - ERROR - Internal Server Error: /ingredients/20/
Traceback (most recent call last):
  File "C:\Users\holmi\PycharmProjects\djangoProject\.venv\Lib\site-packages\django\core\handlers\exception.py", line 55, in inner
    response = get_response(request)
               ^^^^^^^^^^^^^^^^^^^^^
  File "C:\Users\holmi\PycharmProjects\djangoProject\.venv\Lib\site-packages\django\core\handlers\base.py", line 197, in _get_response
    response = wrapped_callback(request, *callback_args, **callback_kwargs)
               ^^^^^^^^^^^^^^^^^^^^^^^^^^^^^^^^^^^^^^^^^^^^^^^^^^^^^^^^^^^^
  File "C:\Users\holmi\PycharmProjects\djangoProject\.venv\Lib\site-packages\django\views\decorators\csrf.py", line 65, in _view_wrapper
    return view_func(request, *args, **kwargs)
           ^^^^^^^^^^^^^^^^^^^^^^^^^^^^^^^^^^^
  File "C:\Users\holmi\PycharmProjects\djangoProject\.venv\Lib\site-packages\rest_framework\viewsets.py", line 125, in view
    return self.dispatch(request, *args, **kwargs)
           ^^^^^^^^^^^^^^^^^^^^^^^^^^^^^^^^^^^^^^^
  File "C:\Users\holmi\PycharmProjects\djangoProject\.venv\Lib\site-packages\rest_framework\views.py", line 509, in dispatch
    response = self.handle_exception(exc)
               ^^^^^^^^^^^^^^^^^^^^^^^^^^
  File "C:\Users\holmi\PycharmProjects\djangoProject\.venv\Lib\site-packages\rest_framework\views.py", line 469, in handle_exception
    self.raise_uncaught_exception(exc)
  File "C:\Users\holmi\PycharmProjects\djangoProject\.venv\Lib\site-packages\rest_framework\views.py", line 480, in raise_uncaught_exception
    raise exc
  File "C:\Users\holmi\PycharmProjects\djangoProject\.venv\Lib\site-packages\rest_framework\views.py", line 506, in dispatch
    response = handler(request, *args, **kwargs)
               ^^^^^^^^^^^^^^^^^^^^^^^^^^^^^^^^^
  File "C:\Users\holmi\PycharmProjects\djangoProject\.venv\Lib\site-packages\rest_framework\mixins.py", line 56, in retrieve
    return Response(serializer.data)
                    ^^^^^^^^^^^^^^^
  File "C:\Users\holmi\PycharmProjects\djangoProject\.venv\Lib\site-packages\rest_framework\serializers.py", line 555, in data
    ret = super().data
          ^^^^^^^^^^^^
  File "C:\Users\holmi\PycharmProjects\djangoProject\.venv\Lib\site-packages\rest_framework\serializers.py", line 253, in data
    self._data = self.to_representation(self.instance)
                 ^^^^^^^^^^^^^^^^^^^^^^^^^^^^^^^^^^^^^
  File "C:\Users\holmi\PycharmProjects\djangoProject\.venv\Lib\site-packages\rest_framework\serializers.py", line 507, in to_representation
    for field in fields:
  File "C:\Users\holmi\PycharmProjects\djangoProject\.venv\Lib\site-packages\rest_framework\serializers.py", line 368, in _readable_fields
    for field in self.fields.values():
                 ^^^^^^^^^^^
  File "C:\Users\holmi\PycharmProjects\djangoProject\.venv\Lib\site-packages\django\utils\functional.py", line 47, in __get__
    res = instance.__dict__[self.name] = self.func(instance)
                                         ^^^^^^^^^^^^^^^^^^^
  File "C:\Users\holmi\PycharmProjects\djangoProject\.venv\Lib\site-packages\rest_framework\serializers.py", line 356, in fields
    for key, value in self.get_fields().items():
                      ^^^^^^^^^^^^^^^^^
  File "C:\Users\holmi\PycharmProjects\djangoProject\.venv\Lib\site-packages\rest_framework\serializers.py", line 1052, in get_fields
    field_names = self.get_field_names(declared_fields, info)
                  ^^^^^^^^^^^^^^^^^^^^^^^^^^^^^^^^^^^^^^^^^^^
  File "C:\Users\holmi\PycharmProjects\djangoProject\.venv\Lib\site-packages\rest_framework\serializers.py", line 1106, in get_field_names
    raise TypeError(
TypeError: The `fields` option must be a list or tuple or "__all__". Got str.
2024-03-07 10:12:51,947 - ERROR - Internal Server Error: /ingredients/20/
Traceback (most recent call last):
  File "C:\Users\holmi\PycharmProjects\djangoProject\.venv\Lib\site-packages\django\core\handlers\exception.py", line 55, in inner
    response = get_response(request)
               ^^^^^^^^^^^^^^^^^^^^^
  File "C:\Users\holmi\PycharmProjects\djangoProject\.venv\Lib\site-packages\django\core\handlers\base.py", line 197, in _get_response
    response = wrapped_callback(request, *callback_args, **callback_kwargs)
               ^^^^^^^^^^^^^^^^^^^^^^^^^^^^^^^^^^^^^^^^^^^^^^^^^^^^^^^^^^^^
  File "C:\Users\holmi\PycharmProjects\djangoProject\.venv\Lib\site-packages\django\views\decorators\csrf.py", line 65, in _view_wrapper
    return view_func(request, *args, **kwargs)
           ^^^^^^^^^^^^^^^^^^^^^^^^^^^^^^^^^^^
  File "C:\Users\holmi\PycharmProjects\djangoProject\.venv\Lib\site-packages\rest_framework\viewsets.py", line 125, in view
    return self.dispatch(request, *args, **kwargs)
           ^^^^^^^^^^^^^^^^^^^^^^^^^^^^^^^^^^^^^^^
  File "C:\Users\holmi\PycharmProjects\djangoProject\.venv\Lib\site-packages\rest_framework\views.py", line 509, in dispatch
    response = self.handle_exception(exc)
               ^^^^^^^^^^^^^^^^^^^^^^^^^^
  File "C:\Users\holmi\PycharmProjects\djangoProject\.venv\Lib\site-packages\rest_framework\views.py", line 469, in handle_exception
    self.raise_uncaught_exception(exc)
  File "C:\Users\holmi\PycharmProjects\djangoProject\.venv\Lib\site-packages\rest_framework\views.py", line 480, in raise_uncaught_exception
    raise exc
  File "C:\Users\holmi\PycharmProjects\djangoProject\.venv\Lib\site-packages\rest_framework\views.py", line 506, in dispatch
    response = handler(request, *args, **kwargs)
               ^^^^^^^^^^^^^^^^^^^^^^^^^^^^^^^^^
  File "C:\Users\holmi\PycharmProjects\djangoProject\.venv\Lib\site-packages\rest_framework\mixins.py", line 56, in retrieve
    return Response(serializer.data)
                    ^^^^^^^^^^^^^^^
  File "C:\Users\holmi\PycharmProjects\djangoProject\.venv\Lib\site-packages\rest_framework\serializers.py", line 555, in data
    ret = super().data
          ^^^^^^^^^^^^
  File "C:\Users\holmi\PycharmProjects\djangoProject\.venv\Lib\site-packages\rest_framework\serializers.py", line 253, in data
    self._data = self.to_representation(self.instance)
                 ^^^^^^^^^^^^^^^^^^^^^^^^^^^^^^^^^^^^^
  File "C:\Users\holmi\PycharmProjects\djangoProject\.venv\Lib\site-packages\rest_framework\serializers.py", line 507, in to_representation
    for field in fields:
  File "C:\Users\holmi\PycharmProjects\djangoProject\.venv\Lib\site-packages\rest_framework\serializers.py", line 368, in _readable_fields
    for field in self.fields.values():
                 ^^^^^^^^^^^
  File "C:\Users\holmi\PycharmProjects\djangoProject\.venv\Lib\site-packages\django\utils\functional.py", line 47, in __get__
    res = instance.__dict__[self.name] = self.func(instance)
                                         ^^^^^^^^^^^^^^^^^^^
  File "C:\Users\holmi\PycharmProjects\djangoProject\.venv\Lib\site-packages\rest_framework\serializers.py", line 356, in fields
    for key, value in self.get_fields().items():
                      ^^^^^^^^^^^^^^^^^
  File "C:\Users\holmi\PycharmProjects\djangoProject\.venv\Lib\site-packages\rest_framework\serializers.py", line 1052, in get_fields
    field_names = self.get_field_names(declared_fields, info)
                  ^^^^^^^^^^^^^^^^^^^^^^^^^^^^^^^^^^^^^^^^^^^
  File "C:\Users\holmi\PycharmProjects\djangoProject\.venv\Lib\site-packages\rest_framework\serializers.py", line 1106, in get_field_names
    raise TypeError(
TypeError: The `fields` option must be a list or tuple or "__all__". Got str.
2024-03-07 10:13:00,185 - ERROR - Internal Server Error: /ingredients/
Traceback (most recent call last):
  File "C:\Users\holmi\PycharmProjects\djangoProject\.venv\Lib\site-packages\django\core\handlers\exception.py", line 55, in inner
    response = get_response(request)
               ^^^^^^^^^^^^^^^^^^^^^
  File "C:\Users\holmi\PycharmProjects\djangoProject\.venv\Lib\site-packages\django\core\handlers\base.py", line 197, in _get_response
    response = wrapped_callback(request, *callback_args, **callback_kwargs)
               ^^^^^^^^^^^^^^^^^^^^^^^^^^^^^^^^^^^^^^^^^^^^^^^^^^^^^^^^^^^^
  File "C:\Users\holmi\PycharmProjects\djangoProject\.venv\Lib\site-packages\django\views\decorators\csrf.py", line 65, in _view_wrapper
    return view_func(request, *args, **kwargs)
           ^^^^^^^^^^^^^^^^^^^^^^^^^^^^^^^^^^^
  File "C:\Users\holmi\PycharmProjects\djangoProject\.venv\Lib\site-packages\rest_framework\viewsets.py", line 125, in view
    return self.dispatch(request, *args, **kwargs)
           ^^^^^^^^^^^^^^^^^^^^^^^^^^^^^^^^^^^^^^^
  File "C:\Users\holmi\PycharmProjects\djangoProject\.venv\Lib\site-packages\rest_framework\views.py", line 509, in dispatch
    response = self.handle_exception(exc)
               ^^^^^^^^^^^^^^^^^^^^^^^^^^
  File "C:\Users\holmi\PycharmProjects\djangoProject\.venv\Lib\site-packages\rest_framework\views.py", line 469, in handle_exception
    self.raise_uncaught_exception(exc)
  File "C:\Users\holmi\PycharmProjects\djangoProject\.venv\Lib\site-packages\rest_framework\views.py", line 480, in raise_uncaught_exception
    raise exc
  File "C:\Users\holmi\PycharmProjects\djangoProject\.venv\Lib\site-packages\rest_framework\views.py", line 506, in dispatch
    response = handler(request, *args, **kwargs)
               ^^^^^^^^^^^^^^^^^^^^^^^^^^^^^^^^^
  File "C:\Users\holmi\PycharmProjects\djangoProject\.venv\Lib\site-packages\rest_framework\mixins.py", line 46, in list
    return Response(serializer.data)
                    ^^^^^^^^^^^^^^^
  File "C:\Users\holmi\PycharmProjects\djangoProject\.venv\Lib\site-packages\rest_framework\serializers.py", line 768, in data
    ret = super().data
          ^^^^^^^^^^^^
  File "C:\Users\holmi\PycharmProjects\djangoProject\.venv\Lib\site-packages\rest_framework\serializers.py", line 253, in data
    self._data = self.to_representation(self.instance)
                 ^^^^^^^^^^^^^^^^^^^^^^^^^^^^^^^^^^^^^
  File "C:\Users\holmi\PycharmProjects\djangoProject\.venv\Lib\site-packages\rest_framework\serializers.py", line 687, in to_representation
    self.child.to_representation(item) for item in iterable
    ^^^^^^^^^^^^^^^^^^^^^^^^^^^^^^^^^^
  File "C:\Users\holmi\PycharmProjects\djangoProject\.venv\Lib\site-packages\rest_framework\serializers.py", line 507, in to_representation
    for field in fields:
  File "C:\Users\holmi\PycharmProjects\djangoProject\.venv\Lib\site-packages\rest_framework\serializers.py", line 368, in _readable_fields
    for field in self.fields.values():
                 ^^^^^^^^^^^
  File "C:\Users\holmi\PycharmProjects\djangoProject\.venv\Lib\site-packages\django\utils\functional.py", line 47, in __get__
    res = instance.__dict__[self.name] = self.func(instance)
                                         ^^^^^^^^^^^^^^^^^^^
  File "C:\Users\holmi\PycharmProjects\djangoProject\.venv\Lib\site-packages\rest_framework\serializers.py", line 356, in fields
    for key, value in self.get_fields().items():
                      ^^^^^^^^^^^^^^^^^
  File "C:\Users\holmi\PycharmProjects\djangoProject\.venv\Lib\site-packages\rest_framework\serializers.py", line 1052, in get_fields
    field_names = self.get_field_names(declared_fields, info)
                  ^^^^^^^^^^^^^^^^^^^^^^^^^^^^^^^^^^^^^^^^^^^
  File "C:\Users\holmi\PycharmProjects\djangoProject\.venv\Lib\site-packages\rest_framework\serializers.py", line 1106, in get_field_names
    raise TypeError(
TypeError: The `fields` option must be a list or tuple or "__all__". Got str.
2024-03-07 10:13:27,223 - INFO - Watching for file changes with StatReloader
2024-03-07 10:20:44,390 - INFO - Watching for file changes with StatReloader
2024-03-07 10:20:52,779 - ERROR - Error createing ingredient: [ErrorDetail(string='Moda', code='invalid')]
2024-03-07 10:20:52,779 - WARNING - Bad Request: /ingredients/create/
2024-03-07 10:21:08,368 - WARNING - Not Found: /ingredients/4145/delete/
2024-03-07 10:21:15,010 - WARNING - Not Found: /ingredients/45/delete/
2024-03-07 10:21:22,158 - WARNING - Not Found: /ingredients/43delete/
2024-03-07 10:21:52,427 - WARNING - Not Found: /ingredients/50delete/
2024-03-07 10:22:09,221 - ERROR - Error destroying ingredient: {'non_field_errors': [ErrorDetail(string='No data provided', code='null')]}
2024-03-07 10:22:09,221 - WARNING - Bad Request: /ingredients/50/delete/
2024-03-07 10:22:41,119 - ERROR - Error destroying ingredient: {'non_field_errors': [ErrorDetail(string='No data provided', code='null')]}
2024-03-07 10:22:41,119 - WARNING - Bad Request: /ingredients/50/delete/
2024-03-07 10:23:25,927 - ERROR - Error destroying ingredient: {'non_field_errors': [ErrorDetail(string='No data provided', code='null')]}
2024-03-07 10:23:25,927 - WARNING - Bad Request: /ingredients/48/delete/
2024-03-07 10:25:24,932 - ERROR - Error destroying ingredient: {'non_field_errors': [ErrorDetail(string='No data provided', code='null')]}
2024-03-07 10:25:24,938 - WARNING - Bad Request: /ingredients/50/delete/
2024-03-07 12:29:26,322 - ERROR - Error destroying ingredient: {'non_field_errors': [ErrorDetail(string='No data provided', code='null')]}
2024-03-07 12:29:26,323 - WARNING - Bad Request: /ingredients/50/delete/
2024-03-07 12:35:30,307 - ERROR - Error destroying ingredient: {'non_field_errors': [ErrorDetail(string='No data provided', code='null')]}
2024-03-07 12:35:30,307 - WARNING - Bad Request: /ingredients/50/delete/
2024-03-07 12:35:37,447 - ERROR - Error createing ingredient: [ErrorDetail(string='Moda', code='invalid')]
2024-03-07 12:35:37,447 - WARNING - Bad Request: /ingredients/create/
2024-03-07 12:37:53,654 - ERROR - Error destroying ingredient: {'non_field_errors': [ErrorDetail(string='No data provided', code='null')]}
2024-03-07 12:37:53,655 - WARNING - Bad Request: /ingredients/50/delete/
2024-03-07 12:38:01,250 - WARNING - Not Found: /ingredients/67/delete/
2024-03-07 12:38:07,887 - ERROR - Error destroying ingredient: {'non_field_errors': [ErrorDetail(string='No data provided', code='null')]}
2024-03-07 12:38:07,888 - WARNING - Bad Request: /ingredients/22/delete/
2024-03-07 12:39:37,755 - ERROR - Error destroying ingredient: {'non_field_errors': [ErrorDetail(string='No data provided', code='null')]}
2024-03-07 12:39:37,755 - WARNING - Bad Request: /ingredients/22/delete/
2024-03-07 12:40:37,287 - INFO - Watching for file changes with StatReloader
2024-03-07 12:41:52,471 - ERROR - Error destroying ingredient: {'non_field_errors': [ErrorDetail(string='No data provided', code='null')]}
2024-03-07 12:41:52,471 - WARNING - Bad Request: /ingredients/22/delete/
2024-03-07 12:43:28,864 - INFO - Watching for file changes with StatReloader
2024-03-07 12:53:54,439 - INFO - Watching for file changes with StatReloader
2024-03-07 12:59:30,529 - INFO - Watching for file changes with StatReloader
2024-03-07 12:59:34,904 - INFO - Watching for file changes with StatReloader
2024-03-07 12:59:59,324 - WARNING - Not Found: /ingredients/21/
2024-03-07 13:02:11,424 - INFO - Watching for file changes with StatReloader
2024-03-07 13:02:16,211 - WARNING - Not Found: /ingredients/21/delete/
2024-03-07 13:11:00,958 - INFO - Watching for file changes with StatReloader
2024-03-07 13:11:08,967 - WARNING - Not Found: /ingredients/17/delete/
2024-03-07 13:11:14,709 - WARNING - Not Found: /ingredients/12/delete/
2024-03-07 13:11:28,471 - WARNING - Not Found: /ingredients/21/
2024-03-07 13:16:53,453 - INFO - Watching for file changes with StatReloader
2024-03-07 13:17:22,649 - INFO - Watching for file changes with StatReloader
2024-03-07 13:17:34,302 - WARNING - Unauthorized: /ingredients/
2024-03-07 13:18:25,290 - WARNING - Unauthorized: /ingredients/create/
2024-03-07 13:18:30,246 - WARNING - Unauthorized: /ingredients/11/delete/
2024-03-07 13:18:49,600 - INFO - Watching for file changes with StatReloader
2024-03-07 13:18:59,039 - WARNING - Unauthorized: /ingredients/
2024-03-07 13:22:54,725 - INFO - Watching for file changes with StatReloader
2024-03-07 13:22:59,258 - WARNING - Unauthorized: /ingredients/
2024-03-07 13:23:06,318 - WARNING - Unauthorized: /ingredients/create/
2024-03-07 13:27:11,769 - WARNING - Method Not Allowed: /auth/sign-in/customer/
2024-03-07 13:27:17,558 - WARNING - Bad Request: /auth/sign-in/customer/
2024-03-07 13:27:45,551 - WARNING - Unauthorized: /ingredients/create/
2024-03-07 13:31:43,967 - WARNING - Unauthorized: /ingredients/create/
2024-03-07 13:32:02,721 - WARNING - Unauthorized: /ingredients/create/
2024-03-07 13:34:19,772 - WARNING - Unauthorized: /ingredients/create/
2024-03-07 13:36:03,274 - WARNING - Unauthorized: /ingredients/create/
2024-03-07 13:37:21,579 - WARNING - Unauthorized: /ingredients/create/
2024-03-07 13:39:24,521 - WARNING - Unauthorized: /ingredients/create/
2024-03-07 13:40:59,490 - WARNING - Unauthorized: /ingredients/create/
2024-03-07 13:49:14,645 - INFO - Watching for file changes with StatReloader
2024-03-07 13:49:19,803 - INFO - Watching for file changes with StatReloader
2024-03-07 13:49:26,147 - WARNING - Unauthorized: /ingredients/
2024-03-07 13:51:07,171 - WARNING - Unauthorized: /ingredients/create/
2024-03-07 14:11:17,515 - WARNING - Unauthorized: /ingredients/61/delete/
2024-03-07 14:11:32,693 - WARNING - Unauthorized: /ingredients/61/delete/
2024-03-07 14:13:54,163 - INFO - Watching for file changes with StatReloader
2024-03-07 14:13:57,787 - WARNING - Unauthorized: /ingredients/59/delete/
2024-03-07 14:14:27,882 - WARNING - Unauthorized: /ingredients/59/delete/
2024-03-07 14:14:48,444 - ERROR - Ошибка при регистрации пользователя: ОШИБКА:  повторяющееся значение ключа нарушает ограничение уникальности "auth_user_username_key"
DETAIL:  Ключ "(username)=(Nek)" уже существует.

2024-03-07 14:14:48,444 - ERROR - Internal Server Error: /auth/sign-up/customer/
2024-03-07 14:17:20,900 - WARNING - Method Not Allowed: /ingredients/59/delete/
2024-03-07 14:17:39,583 - WARNING - Not Found: /ingredients/59/create/
2024-03-07 14:19:35,245 - INFO - Watching for file changes with StatReloader
2024-03-07 14:21:19,264 - INFO - C:\Users\holmi\PycharmProjects\djangoProject\Mamma_Mia\views.py changed, reloading.
2024-03-07 14:21:20,130 - INFO - Watching for file changes with StatReloader
2024-03-07 14:25:35,148 - INFO - Watching for file changes with StatReloader
2024-03-07 14:25:50,681 - WARNING - Unauthorized: /ingredients/
2024-03-07 14:26:08,942 - WARNING - Unauthorized: /ingredients/create/
2024-03-07 14:26:25,023 - ERROR - Ошибка при регистрации пользователя: ОШИБКА:  повторяющееся значение ключа нарушает ограничение уникальности "auth_user_username_key"
DETAIL:  Ключ "(username)=(Nek)" уже существует.

2024-03-07 14:26:25,023 - ERROR - Internal Server Error: /auth/sign-up/customer/
2024-03-07 14:28:31,867 - INFO - Watching for file changes with StatReloader
2024-03-07 14:28:39,020 - WARNING - Unauthorized: /ingredients/
2024-03-07 14:28:46,129 - WARNING - Forbidden: /ingredients/
2024-03-07 14:29:17,308 - WARNING - Forbidden: /ingredients/
2024-03-07 14:30:17,787 - WARNING - Unauthorized: /ingredients/create/
2024-03-07 14:30:21,743 - WARNING - Unauthorized: /ingredients/create/
2024-03-07 14:30:48,097 - WARNING - Unauthorized: /ingredients/61/delete/
2024-03-07 14:31:03,962 - WARNING - Unauthorized: /ingredients/61/delete/
2024-03-07 14:31:16,422 - WARNING - Not Found: /ingredients/61/delete/
2024-03-07 14:33:10,593 - INFO - Watching for file changes with StatReloader
2024-03-07 14:37:32,463 - INFO - C:\Users\holmi\PycharmProjects\djangoProject\Mamma_Mia\views.py changed, reloading.
2024-03-07 14:37:33,409 - INFO - Watching for file changes with StatReloader
2024-03-07 14:41:36,685 - INFO - Watching for file changes with StatReloader
2024-03-07 14:41:44,260 - WARNING - Unauthorized: /ingredients/
2024-03-07 14:41:52,641 - WARNING - Unauthorized: /ingredients/create/
2024-03-07 14:42:24,287 - WARNING - Unauthorized: /ingredients/create/
2024-03-07 14:45:52,079 - INFO - Watching for file changes with StatReloader
2024-03-07 14:45:57,715 - WARNING - Unauthorized: /ingredients/
2024-03-07 14:46:03,638 - WARNING - Unauthorized: /ingredients/
2024-03-07 14:46:28,262 - INFO - Watching for file changes with StatReloader
2024-03-07 14:46:32,946 - WARNING - Unauthorized: /ingredients/
2024-03-07 14:46:57,368 - INFO - Watching for file changes with StatReloader
2024-03-07 14:47:05,751 - WARNING - Unauthorized: /ingredients/
2024-03-07 14:48:07,661 - WARNING - Not Found: /ingredients/65/delete/
2024-03-07 14:48:23,281 - WARNING - Unauthorized: /ingredients/create/
2024-03-07 14:49:33,786 - INFO - Watching for file changes with StatReloader
2024-03-07 14:50:20,327 - INFO - Watching for file changes with StatReloader
2024-03-07 14:50:45,713 - WARNING - Unauthorized: /pizzas/create/
2024-03-07 14:51:14,976 - ERROR - Error createing pizza: {'dough_type': [ErrorDetail(string='"THin" is not a valid choice.', code='invalid_choice')]}
2024-03-07 14:51:14,976 - WARNING - Bad Request: /pizzas/create/
2024-03-07 14:54:01,534 - WARNING - Unauthorized: /pizza/1/
2024-03-07 14:54:34,477 - WARNING - Not Found: /pizzas/2/delete/
2024-03-07 14:55:01,448 - WARNING - Bad Request: /pizzas/1/update/
2024-03-07 14:56:05,221 - INFO - Watching for file changes with StatReloader
2024-03-07 14:56:15,727 - WARNING - Not Found: /toppings/1/
2024-03-07 14:58:29,201 - INFO - Watching for file changes with StatReloader
2024-03-07 15:02:02,962 - INFO - C:\Users\holmi\PycharmProjects\djangoProject\Mamma_Mia\urls.py changed, reloading.
2024-03-07 15:02:03,668 - INFO - Watching for file changes with StatReloader
2024-03-07 15:02:15,670 - ERROR - Internal Server Error: /customers/
Traceback (most recent call last):
  File "C:\Users\holmi\PycharmProjects\djangoProject\.venv\Lib\site-packages\django\core\handlers\exception.py", line 55, in inner
    response = get_response(request)
               ^^^^^^^^^^^^^^^^^^^^^
  File "C:\Users\holmi\PycharmProjects\djangoProject\.venv\Lib\site-packages\django\core\handlers\base.py", line 197, in _get_response
    response = wrapped_callback(request, *callback_args, **callback_kwargs)
               ^^^^^^^^^^^^^^^^^^^^^^^^^^^^^^^^^^^^^^^^^^^^^^^^^^^^^^^^^^^^
  File "C:\Users\holmi\PycharmProjects\djangoProject\.venv\Lib\site-packages\django\views\decorators\csrf.py", line 65, in _view_wrapper
    return view_func(request, *args, **kwargs)
           ^^^^^^^^^^^^^^^^^^^^^^^^^^^^^^^^^^^
  File "C:\Users\holmi\PycharmProjects\djangoProject\.venv\Lib\site-packages\rest_framework\viewsets.py", line 125, in view
    return self.dispatch(request, *args, **kwargs)
           ^^^^^^^^^^^^^^^^^^^^^^^^^^^^^^^^^^^^^^^
  File "C:\Users\holmi\PycharmProjects\djangoProject\.venv\Lib\site-packages\rest_framework\views.py", line 509, in dispatch
    response = self.handle_exception(exc)
               ^^^^^^^^^^^^^^^^^^^^^^^^^^
  File "C:\Users\holmi\PycharmProjects\djangoProject\.venv\Lib\site-packages\rest_framework\views.py", line 469, in handle_exception
    self.raise_uncaught_exception(exc)
  File "C:\Users\holmi\PycharmProjects\djangoProject\.venv\Lib\site-packages\rest_framework\views.py", line 480, in raise_uncaught_exception
    raise exc
  File "C:\Users\holmi\PycharmProjects\djangoProject\.venv\Lib\site-packages\rest_framework\views.py", line 506, in dispatch
    response = handler(request, *args, **kwargs)
               ^^^^^^^^^^^^^^^^^^^^^^^^^^^^^^^^^
  File "C:\Users\holmi\PycharmProjects\djangoProject\.venv\Lib\site-packages\rest_framework\mixins.py", line 46, in list
    return Response(serializer.data)
                    ^^^^^^^^^^^^^^^
  File "C:\Users\holmi\PycharmProjects\djangoProject\.venv\Lib\site-packages\rest_framework\serializers.py", line 768, in data
    ret = super().data
          ^^^^^^^^^^^^
  File "C:\Users\holmi\PycharmProjects\djangoProject\.venv\Lib\site-packages\rest_framework\serializers.py", line 253, in data
    self._data = self.to_representation(self.instance)
                 ^^^^^^^^^^^^^^^^^^^^^^^^^^^^^^^^^^^^^
  File "C:\Users\holmi\PycharmProjects\djangoProject\.venv\Lib\site-packages\rest_framework\serializers.py", line 687, in to_representation
    self.child.to_representation(item) for item in iterable
    ^^^^^^^^^^^^^^^^^^^^^^^^^^^^^^^^^^
  File "C:\Users\holmi\PycharmProjects\djangoProject\.venv\Lib\site-packages\rest_framework\serializers.py", line 507, in to_representation
    for field in fields:
  File "C:\Users\holmi\PycharmProjects\djangoProject\.venv\Lib\site-packages\rest_framework\serializers.py", line 368, in _readable_fields
    for field in self.fields.values():
                 ^^^^^^^^^^^
  File "C:\Users\holmi\PycharmProjects\djangoProject\.venv\Lib\site-packages\django\utils\functional.py", line 47, in __get__
    res = instance.__dict__[self.name] = self.func(instance)
                                         ^^^^^^^^^^^^^^^^^^^
  File "C:\Users\holmi\PycharmProjects\djangoProject\.venv\Lib\site-packages\rest_framework\serializers.py", line 356, in fields
    for key, value in self.get_fields().items():
                      ^^^^^^^^^^^^^^^^^
  File "C:\Users\holmi\PycharmProjects\djangoProject\.venv\Lib\site-packages\rest_framework\serializers.py", line 1052, in get_fields
    field_names = self.get_field_names(declared_fields, info)
                  ^^^^^^^^^^^^^^^^^^^^^^^^^^^^^^^^^^^^^^^^^^^
  File "C:\Users\holmi\PycharmProjects\djangoProject\.venv\Lib\site-packages\rest_framework\serializers.py", line 1106, in get_field_names
    raise TypeError(
TypeError: The `fields` option must be a list or tuple or "__all__". Got str.
2024-03-07 15:02:32,250 - INFO - Watching for file changes with StatReloader
2024-03-07 15:02:40,172 - ERROR - Internal Server Error: /customers/
Traceback (most recent call last):
  File "C:\Users\holmi\PycharmProjects\djangoProject\.venv\Lib\site-packages\django\core\handlers\exception.py", line 55, in inner
    response = get_response(request)
               ^^^^^^^^^^^^^^^^^^^^^
  File "C:\Users\holmi\PycharmProjects\djangoProject\.venv\Lib\site-packages\django\core\handlers\base.py", line 197, in _get_response
    response = wrapped_callback(request, *callback_args, **callback_kwargs)
               ^^^^^^^^^^^^^^^^^^^^^^^^^^^^^^^^^^^^^^^^^^^^^^^^^^^^^^^^^^^^
  File "C:\Users\holmi\PycharmProjects\djangoProject\.venv\Lib\site-packages\django\views\decorators\csrf.py", line 65, in _view_wrapper
    return view_func(request, *args, **kwargs)
           ^^^^^^^^^^^^^^^^^^^^^^^^^^^^^^^^^^^
  File "C:\Users\holmi\PycharmProjects\djangoProject\.venv\Lib\site-packages\rest_framework\viewsets.py", line 125, in view
    return self.dispatch(request, *args, **kwargs)
           ^^^^^^^^^^^^^^^^^^^^^^^^^^^^^^^^^^^^^^^
  File "C:\Users\holmi\PycharmProjects\djangoProject\.venv\Lib\site-packages\rest_framework\views.py", line 509, in dispatch
    response = self.handle_exception(exc)
               ^^^^^^^^^^^^^^^^^^^^^^^^^^
  File "C:\Users\holmi\PycharmProjects\djangoProject\.venv\Lib\site-packages\rest_framework\views.py", line 469, in handle_exception
    self.raise_uncaught_exception(exc)
  File "C:\Users\holmi\PycharmProjects\djangoProject\.venv\Lib\site-packages\rest_framework\views.py", line 480, in raise_uncaught_exception
    raise exc
  File "C:\Users\holmi\PycharmProjects\djangoProject\.venv\Lib\site-packages\rest_framework\views.py", line 506, in dispatch
    response = handler(request, *args, **kwargs)
               ^^^^^^^^^^^^^^^^^^^^^^^^^^^^^^^^^
  File "C:\Users\holmi\PycharmProjects\djangoProject\.venv\Lib\site-packages\rest_framework\mixins.py", line 46, in list
    return Response(serializer.data)
                    ^^^^^^^^^^^^^^^
  File "C:\Users\holmi\PycharmProjects\djangoProject\.venv\Lib\site-packages\rest_framework\serializers.py", line 768, in data
    ret = super().data
          ^^^^^^^^^^^^
  File "C:\Users\holmi\PycharmProjects\djangoProject\.venv\Lib\site-packages\rest_framework\serializers.py", line 253, in data
    self._data = self.to_representation(self.instance)
                 ^^^^^^^^^^^^^^^^^^^^^^^^^^^^^^^^^^^^^
  File "C:\Users\holmi\PycharmProjects\djangoProject\.venv\Lib\site-packages\rest_framework\serializers.py", line 687, in to_representation
    self.child.to_representation(item) for item in iterable
    ^^^^^^^^^^^^^^^^^^^^^^^^^^^^^^^^^^
  File "C:\Users\holmi\PycharmProjects\djangoProject\.venv\Lib\site-packages\rest_framework\serializers.py", line 507, in to_representation
    for field in fields:
  File "C:\Users\holmi\PycharmProjects\djangoProject\.venv\Lib\site-packages\rest_framework\serializers.py", line 368, in _readable_fields
    for field in self.fields.values():
                 ^^^^^^^^^^^
  File "C:\Users\holmi\PycharmProjects\djangoProject\.venv\Lib\site-packages\django\utils\functional.py", line 47, in __get__
    res = instance.__dict__[self.name] = self.func(instance)
                                         ^^^^^^^^^^^^^^^^^^^
  File "C:\Users\holmi\PycharmProjects\djangoProject\.venv\Lib\site-packages\rest_framework\serializers.py", line 356, in fields
    for key, value in self.get_fields().items():
                      ^^^^^^^^^^^^^^^^^
  File "C:\Users\holmi\PycharmProjects\djangoProject\.venv\Lib\site-packages\rest_framework\serializers.py", line 1052, in get_fields
    field_names = self.get_field_names(declared_fields, info)
                  ^^^^^^^^^^^^^^^^^^^^^^^^^^^^^^^^^^^^^^^^^^^
  File "C:\Users\holmi\PycharmProjects\djangoProject\.venv\Lib\site-packages\rest_framework\serializers.py", line 1106, in get_field_names
    raise TypeError(
TypeError: The `fields` option must be a list or tuple or "__all__". Got str.
2024-03-07 15:03:13,604 - ERROR - Internal Server Error: /customers/
Traceback (most recent call last):
  File "C:\Users\holmi\PycharmProjects\djangoProject\.venv\Lib\site-packages\django\core\handlers\exception.py", line 55, in inner
    response = get_response(request)
               ^^^^^^^^^^^^^^^^^^^^^
  File "C:\Users\holmi\PycharmProjects\djangoProject\.venv\Lib\site-packages\django\core\handlers\base.py", line 197, in _get_response
    response = wrapped_callback(request, *callback_args, **callback_kwargs)
               ^^^^^^^^^^^^^^^^^^^^^^^^^^^^^^^^^^^^^^^^^^^^^^^^^^^^^^^^^^^^
  File "C:\Users\holmi\PycharmProjects\djangoProject\.venv\Lib\site-packages\django\views\decorators\csrf.py", line 65, in _view_wrapper
    return view_func(request, *args, **kwargs)
           ^^^^^^^^^^^^^^^^^^^^^^^^^^^^^^^^^^^
  File "C:\Users\holmi\PycharmProjects\djangoProject\.venv\Lib\site-packages\rest_framework\viewsets.py", line 125, in view
    return self.dispatch(request, *args, **kwargs)
           ^^^^^^^^^^^^^^^^^^^^^^^^^^^^^^^^^^^^^^^
  File "C:\Users\holmi\PycharmProjects\djangoProject\.venv\Lib\site-packages\rest_framework\views.py", line 509, in dispatch
    response = self.handle_exception(exc)
               ^^^^^^^^^^^^^^^^^^^^^^^^^^
  File "C:\Users\holmi\PycharmProjects\djangoProject\.venv\Lib\site-packages\rest_framework\views.py", line 469, in handle_exception
    self.raise_uncaught_exception(exc)
  File "C:\Users\holmi\PycharmProjects\djangoProject\.venv\Lib\site-packages\rest_framework\views.py", line 480, in raise_uncaught_exception
    raise exc
  File "C:\Users\holmi\PycharmProjects\djangoProject\.venv\Lib\site-packages\rest_framework\views.py", line 506, in dispatch
    response = handler(request, *args, **kwargs)
               ^^^^^^^^^^^^^^^^^^^^^^^^^^^^^^^^^
  File "C:\Users\holmi\PycharmProjects\djangoProject\.venv\Lib\site-packages\rest_framework\mixins.py", line 46, in list
    return Response(serializer.data)
                    ^^^^^^^^^^^^^^^
  File "C:\Users\holmi\PycharmProjects\djangoProject\.venv\Lib\site-packages\rest_framework\serializers.py", line 768, in data
    ret = super().data
          ^^^^^^^^^^^^
  File "C:\Users\holmi\PycharmProjects\djangoProject\.venv\Lib\site-packages\rest_framework\serializers.py", line 253, in data
    self._data = self.to_representation(self.instance)
                 ^^^^^^^^^^^^^^^^^^^^^^^^^^^^^^^^^^^^^
  File "C:\Users\holmi\PycharmProjects\djangoProject\.venv\Lib\site-packages\rest_framework\serializers.py", line 687, in to_representation
    self.child.to_representation(item) for item in iterable
    ^^^^^^^^^^^^^^^^^^^^^^^^^^^^^^^^^^
  File "C:\Users\holmi\PycharmProjects\djangoProject\.venv\Lib\site-packages\rest_framework\serializers.py", line 507, in to_representation
    for field in fields:
  File "C:\Users\holmi\PycharmProjects\djangoProject\.venv\Lib\site-packages\rest_framework\serializers.py", line 368, in _readable_fields
    for field in self.fields.values():
                 ^^^^^^^^^^^
  File "C:\Users\holmi\PycharmProjects\djangoProject\.venv\Lib\site-packages\django\utils\functional.py", line 47, in __get__
    res = instance.__dict__[self.name] = self.func(instance)
                                         ^^^^^^^^^^^^^^^^^^^
  File "C:\Users\holmi\PycharmProjects\djangoProject\.venv\Lib\site-packages\rest_framework\serializers.py", line 356, in fields
    for key, value in self.get_fields().items():
                      ^^^^^^^^^^^^^^^^^
  File "C:\Users\holmi\PycharmProjects\djangoProject\.venv\Lib\site-packages\rest_framework\serializers.py", line 1052, in get_fields
    field_names = self.get_field_names(declared_fields, info)
                  ^^^^^^^^^^^^^^^^^^^^^^^^^^^^^^^^^^^^^^^^^^^
  File "C:\Users\holmi\PycharmProjects\djangoProject\.venv\Lib\site-packages\rest_framework\serializers.py", line 1106, in get_field_names
    raise TypeError(
TypeError: The `fields` option must be a list or tuple or "__all__". Got str.
2024-03-07 15:03:42,969 - INFO - Watching for file changes with StatReloader
2024-03-07 15:08:04,177 - INFO - C:\Users\holmi\PycharmProjects\djangoProject\Mamma_Mia\views.py changed, reloading.
2024-03-07 15:08:04,968 - INFO - Watching for file changes with StatReloader
2024-03-07 15:08:13,871 - ERROR - Internal Server Error: /orders
Traceback (most recent call last):
  File "C:\Users\holmi\PycharmProjects\djangoProject\.venv\Lib\site-packages\django\core\handlers\exception.py", line 55, in inner
    response = get_response(request)
               ^^^^^^^^^^^^^^^^^^^^^
  File "C:\Users\holmi\PycharmProjects\djangoProject\.venv\Lib\site-packages\django\utils\deprecation.py", line 136, in __call__
    response = self.process_response(request, response)
               ^^^^^^^^^^^^^^^^^^^^^^^^^^^^^^^^^^^^^^^^
  File "C:\Users\holmi\PycharmProjects\djangoProject\.venv\Lib\site-packages\django\middleware\common.py", line 108, in process_response
    return self.response_redirect_class(self.get_full_path_with_slash(request))
                                        ^^^^^^^^^^^^^^^^^^^^^^^^^^^^^^^^^^^^^^
  File "C:\Users\holmi\PycharmProjects\djangoProject\.venv\Lib\site-packages\django\middleware\common.py", line 87, in get_full_path_with_slash
    raise RuntimeError(
RuntimeError: You called this URL via POST, but the URL doesn't end in a slash and you have APPEND_SLASH set. Django can't redirect to the slash URL while maintaining POST data. Change your form to point to localhost:8000/orders/ (note the trailing slash), or set APPEND_SLASH=False in your Django settings.
2024-03-07 15:09:27,619 - WARNING - Not Found: /orders/<int:pk>/
2024-03-07 15:09:32,780 - WARNING - Not Found: /orders/1/
2024-03-07 15:14:14,278 - INFO - C:\Users\holmi\PycharmProjects\djangoProject\Mamma_Mia\views.py changed, reloading.
2024-03-07 15:14:15,176 - INFO - Watching for file changes with StatReloader
2024-03-07 15:23:18,658 - INFO - Watching for file changes with StatReloader
2024-03-07 15:23:36,476 - INFO - Watching for file changes with StatReloader
2024-03-07 15:27:19,794 - INFO - Watching for file changes with StatReloader
2024-03-07 15:31:29,781 - INFO - run server
2024-03-07 15:31:55,155 - WARNING - Unauthorized: /ingredients/
2024-03-07 15:33:51,839 - WARNING - Not Found: /ingredients/create/
2024-03-07 15:34:20,495 - WARNING - Not Found: /ingredients/create/
2024-03-07 15:34:28,137 - WARNING - Not Found: /ingredients/create/
2024-03-07 15:34:53,001 - INFO - Created ingredient 69: {'id': 69, 'name': 'bek'}
2024-03-07 15:35:13,134 - WARNING - Unauthorized: /ingredients/2/
2024-03-07 15:35:55,883 - WARNING - Not Found: /ingredients/63/delete/
2024-03-07 15:36:10,400 - WARNING - Forbidden: /ingredients/63/details/
2024-03-07 15:36:43,935 - WARNING - Not Found: /ingredients/63/details/
2024-03-07 15:37:04,353 - WARNING - Unauthorized: /ingredients/new_ingr/
2024-03-07 15:37:49,922 - WARNING - Unauthorized: /pizzas/new_pizza/
2024-03-07 15:38:51,379 - INFO - Created pizza 4: {'id': 4, 'name': 'test1', 'description': 'Classic Italian pizza with tomato sauce, mozzarella cheese, and fresh basil.', 'price': '9.99', 'size': 'Medium', 'category': 'Vegetarian', 'dough_type': 'Thin', 'ingredients': [1, 3, 5]}
2024-03-07 15:39:02,698 - INFO - Created pizza 5: {'id': 5, 'name': 'test1', 'description': 'Classic Italian pizza with tomato sauce, mozzarella cheese, and fresh basil.', 'price': '9.99', 'size': 'Medium', 'category': 'Vegetarian', 'dough_type': 'Thin', 'ingredients': [1, 3, 5]}
2024-03-07 15:39:12,346 - WARNING - Unauthorized: /pizzas/
2024-03-07 15:39:18,441 - WARNING - Unauthorized: /pizzas/
2024-03-07 15:39:36,270 - WARNING - Unauthorized: /pizzas/
2024-03-07 15:39:54,722 - WARNING - Unauthorized: /pizzas/
2024-03-07 15:40:35,994 - WARNING - Not Found: /pizzas/2/delete/
2024-03-07 15:40:45,450 - WARNING - Not Found: /pizzas/2/details/
2024-03-07 15:41:00,756 - WARNING - Unauthorized: /pizzas/1/update/
2024-03-07 15:41:08,695 - WARNING - Bad Request: /pizzas/1/update/
2024-03-07 15:41:29,284 - WARNING - Not Found: /toppings/1/
2024-03-07 15:41:34,320 - WARNING - Not Found: /toppings/create/
2024-03-07 15:41:48,421 - INFO - Created topping 11: {'id': 11, 'name': 'Perfect_Cheese', 'price': '10.00'}
2024-03-07 15:42:22,122 - WARNING - Not Found: /toppings/1/details/
2024-03-07 15:42:27,138 - INFO - Deleted topping None
2024-03-07 15:42:37,141 - WARNING - Not Found: /toppings/2/update/
2024-03-07 15:43:09,680 - WARNING - Unauthorized: /orders/
2024-03-07 15:44:44,315 - ERROR - Ошибка при регистрации пользователя: ОШИБКА:  повторяющееся значение ключа нарушает ограничение уникальности "auth_user_username_key"
DETAIL:  Ключ "(username)=(Nek)" уже существует.

2024-03-07 15:44:44,315 - ERROR - Internal Server Error: /auth/sign-up/customer/
2024-03-07 15:44:52,611 - INFO - Пользователь успешно зарегистрирован: Ne
2024-03-07 15:44:56,906 - ERROR - Ошибка при регистрации пользователя: ОШИБКА:  повторяющееся значение ключа нарушает ограничение уникальности "auth_user_username_key"
DETAIL:  Ключ "(username)=(Ne)" уже существует.

2024-03-07 15:44:56,907 - ERROR - Internal Server Error: /auth/sign-up/customer/
2024-03-07 15:45:02,165 - WARNING - Unauthorized: /customers/
2024-03-07 15:45:41,063 - ERROR - Ошибка при регистрации пользователя: ОШИБКА:  повторяющееся значение ключа нарушает ограничение уникальности "auth_user_username_key"
DETAIL:  Ключ "(username)=(Ne)" уже существует.

2024-03-07 15:45:41,064 - ERROR - Internal Server Error: /auth/sign-up/customer/
2024-03-07 15:46:01,017 - ERROR - Ошибка при регистрации пользователя: ОШИБКА:  повторяющееся значение ключа нарушает ограничение уникальности "auth_user_username_key"
DETAIL:  Ключ "(username)=(Ne)" уже существует.

2024-03-07 15:46:01,017 - ERROR - Internal Server Error: /auth/sign-up/customer/
2024-03-07 15:49:28,673 - WARNING - Bad Request: /auth/token/refresh/
2024-03-07 15:50:47,387 - WARNING - Bad Request: /auth/token/refresh/
2024-03-07 15:51:35,491 - WARNING - Method Not Allowed: /auth/token/refresh/
2024-03-07 15:53:36,891 - INFO - Watching for file changes with StatReloader
2024-03-07 15:56:38,687 - INFO - Watching for file changes with StatReloader
2024-03-07 15:57:01,906 - INFO - Watching for file changes with StatReloader
